[2025-02-02T21:38:06.813-0300] {local_task_job_runner.py:123} INFO - ::group::Pre task execution logs
[2025-02-02T21:38:06.818-0300] {taskinstance.py:2613} INFO - Dependencies all met for dep_context=non-requeueable deps ti=<TaskInstance: InsertPACTRATxAGENDIntoElastic.inject_pactrat_agend_into_es scheduled__2021-12-04T00:00:00+00:00 [queued]>
[2025-02-02T21:38:06.823-0300] {taskinstance.py:2613} INFO - Dependencies all met for dep_context=requeueable deps ti=<TaskInstance: InsertPACTRATxAGENDIntoElastic.inject_pactrat_agend_into_es scheduled__2021-12-04T00:00:00+00:00 [queued]>
[2025-02-02T21:38:06.823-0300] {taskinstance.py:2866} INFO - Starting attempt 2 of 2
[2025-02-02T21:38:06.832-0300] {taskinstance.py:2889} INFO - Executing <Task(PythonOperator): inject_pactrat_agend_into_es> on 2021-12-04 00:00:00+00:00
[2025-02-02T21:38:06.836-0300] {standard_task_runner.py:72} INFO - Started process 27532 to run task
[2025-02-02T21:38:06.838-0300] {standard_task_runner.py:104} INFO - Running: ['airflow', 'tasks', 'run', 'InsertPACTRATxAGENDIntoElastic', 'inject_pactrat_agend_into_es', 'scheduled__2021-12-04T00:00:00+00:00', '--job-id', '8324', '--raw', '--subdir', 'DAGS_FOLDER/DAGInjectPACTRATXAGENDElastic.py', '--cfg-path', '/tmp/tmpdelr3t9c']
[2025-02-02T21:38:06.840-0300] {standard_task_runner.py:105} INFO - Job 8324: Subtask inject_pactrat_agend_into_es
[2025-02-02T21:38:06.861-0300] {task_command.py:467} INFO - Running <TaskInstance: InsertPACTRATxAGENDIntoElastic.inject_pactrat_agend_into_es scheduled__2021-12-04T00:00:00+00:00 [running]> on host lucas-Aspire-A514-54
[2025-02-02T21:38:06.990-0300] {taskinstance.py:3132} INFO - Exporting env vars: AIRFLOW_CTX_DAG_OWNER='lucas' AIRFLOW_CTX_DAG_ID='InsertPACTRATxAGENDIntoElastic' AIRFLOW_CTX_TASK_ID='inject_pactrat_agend_into_es' AIRFLOW_CTX_EXECUTION_DATE='2021-12-04T00:00:00+00:00' AIRFLOW_CTX_TRY_NUMBER='2' AIRFLOW_CTX_DAG_RUN_ID='scheduled__2021-12-04T00:00:00+00:00'
[2025-02-02T21:38:06.991-0300] {taskinstance.py:731} INFO - ::endgroup::
[2025-02-02T21:38:07.242-0300] {logging_mixin.py:190} WARNING - /home/lucas/airflow/dags/DAGInjectPACTRATXAGENDElastic.py:138 DtypeWarning: Columns (2) have mixed types. Specify dtype option on import or set low_memory=False.
[2025-02-02T21:38:08.241-0300] {_transport.py:349} INFO - DELETE https://my-elasticsearch-project-a9672d.es.us-east-1.aws.elastic.cloud:443/pacientes_agendamento [status:200 duration:0.819s]
[2025-02-02T21:38:09.333-0300] {_transport.py:349} INFO - PUT https://my-elasticsearch-project-a9672d.es.us-east-1.aws.elastic.cloud:443/pacientes_agendamento [status:200 duration:1.092s]
[2025-02-02T21:38:09.334-0300] {logging_mixin.py:190} INFO - {'acknowledged': True, 'shards_acknowledged': True, 'index': 'pacientes_agendamento'}
[2025-02-02T21:38:22.979-0300] {_transport.py:372} INFO - PUT https://my-elasticsearch-project-a9672d.es.us-east-1.aws.elastic.cloud:443/_bulk [status:N/A duration:10.001s]
[2025-02-02T21:38:22.980-0300] {_node_pool.py:249} WARNING - Node <Urllib3HttpNode(https://my-elasticsearch-project-a9672d.es.us-east-1.aws.elastic.cloud:443)> has failed for 1 times in a row, putting on 1 second timeout
[2025-02-02T21:38:22.980-0300] {_transport.py:415} WARNING - Retrying request after failure (attempt 0 of 3)
Traceback (most recent call last):
  File "/home/lucas/airflow_env/lib/python3.12/site-packages/urllib3/connectionpool.py", line 787, in urlopen
    response = self._make_request(
               ^^^^^^^^^^^^^^^^^^^
  File "/home/lucas/airflow_env/lib/python3.12/site-packages/urllib3/connectionpool.py", line 493, in _make_request
    conn.request(
  File "/home/lucas/airflow_env/lib/python3.12/site-packages/urllib3/connection.py", line 459, in request
    self.send(chunk)
  File "/usr/lib/python3.12/http/client.py", line 1055, in send
    self.sock.sendall(data)
  File "/usr/lib/python3.12/ssl.py", line 1211, in sendall
    v = self.send(byte_view[count:])
        ^^^^^^^^^^^^^^^^^^^^^^^^^^^^
  File "/usr/lib/python3.12/ssl.py", line 1180, in send
    return self._sslobj.write(data)
           ^^^^^^^^^^^^^^^^^^^^^^^^
TimeoutError: The write operation timed out

During handling of the above exception, another exception occurred:

Traceback (most recent call last):
  File "/home/lucas/airflow_env/lib/python3.12/site-packages/elastic_transport/_node/_http_urllib3.py", line 167, in perform_request
    response = self.pool.urlopen(
               ^^^^^^^^^^^^^^^^^^
  File "/home/lucas/airflow_env/lib/python3.12/site-packages/urllib3/connectionpool.py", line 841, in urlopen
    retries = retries.increment(
              ^^^^^^^^^^^^^^^^^^
  File "/home/lucas/airflow_env/lib/python3.12/site-packages/urllib3/util/retry.py", line 449, in increment
    raise reraise(type(error), error, _stacktrace)
          ^^^^^^^^^^^^^^^^^^^^^^^^^^^^^^^^^^^^^^^^
  File "/home/lucas/airflow_env/lib/python3.12/site-packages/urllib3/util/util.py", line 38, in reraise
    raise value.with_traceback(tb)
  File "/home/lucas/airflow_env/lib/python3.12/site-packages/urllib3/connectionpool.py", line 787, in urlopen
    response = self._make_request(
               ^^^^^^^^^^^^^^^^^^^
  File "/home/lucas/airflow_env/lib/python3.12/site-packages/urllib3/connectionpool.py", line 493, in _make_request
    conn.request(
  File "/home/lucas/airflow_env/lib/python3.12/site-packages/urllib3/connection.py", line 459, in request
    self.send(chunk)
  File "/usr/lib/python3.12/http/client.py", line 1055, in send
    self.sock.sendall(data)
  File "/usr/lib/python3.12/ssl.py", line 1211, in sendall
    v = self.send(byte_view[count:])
        ^^^^^^^^^^^^^^^^^^^^^^^^^^^^
  File "/usr/lib/python3.12/ssl.py", line 1180, in send
    return self._sslobj.write(data)
           ^^^^^^^^^^^^^^^^^^^^^^^^
urllib3.exceptions.ProtocolError: ('Connection aborted.', TimeoutError('The write operation timed out'))

The above exception was the direct cause of the following exception:

Traceback (most recent call last):
  File "/home/lucas/airflow_env/lib/python3.12/site-packages/elastic_transport/_transport.py", line 342, in perform_request
    resp = node.perform_request(
           ^^^^^^^^^^^^^^^^^^^^^
  File "/home/lucas/airflow_env/lib/python3.12/site-packages/elastic_transport/_node/_http_urllib3.py", line 202, in perform_request
    raise err from e
elastic_transport.ConnectionError: Connection error caused by: ProtocolError(('Connection aborted.', TimeoutError('The write operation timed out')))
[2025-02-02T21:38:33.307-0300] {_transport.py:372} INFO - PUT https://my-elasticsearch-project-a9672d.es.us-east-1.aws.elastic.cloud:443/_bulk [status:N/A duration:10.320s]
[2025-02-02T21:38:33.307-0300] {_node_pool.py:249} WARNING - Node <Urllib3HttpNode(https://my-elasticsearch-project-a9672d.es.us-east-1.aws.elastic.cloud:443)> has failed for 2 times in a row, putting on 2 second timeout
[2025-02-02T21:38:33.308-0300] {_transport.py:415} WARNING - Retrying request after failure (attempt 1 of 3)
Traceback (most recent call last):
  File "/home/lucas/airflow_env/lib/python3.12/site-packages/urllib3/connectionpool.py", line 787, in urlopen
    response = self._make_request(
               ^^^^^^^^^^^^^^^^^^^
  File "/home/lucas/airflow_env/lib/python3.12/site-packages/urllib3/connectionpool.py", line 493, in _make_request
    conn.request(
  File "/home/lucas/airflow_env/lib/python3.12/site-packages/urllib3/connection.py", line 459, in request
    self.send(chunk)
  File "/usr/lib/python3.12/http/client.py", line 1055, in send
    self.sock.sendall(data)
  File "/usr/lib/python3.12/ssl.py", line 1211, in sendall
    v = self.send(byte_view[count:])
        ^^^^^^^^^^^^^^^^^^^^^^^^^^^^
  File "/usr/lib/python3.12/ssl.py", line 1180, in send
    return self._sslobj.write(data)
           ^^^^^^^^^^^^^^^^^^^^^^^^
TimeoutError: The write operation timed out

During handling of the above exception, another exception occurred:

Traceback (most recent call last):
  File "/home/lucas/airflow_env/lib/python3.12/site-packages/elastic_transport/_node/_http_urllib3.py", line 167, in perform_request
    response = self.pool.urlopen(
               ^^^^^^^^^^^^^^^^^^
  File "/home/lucas/airflow_env/lib/python3.12/site-packages/urllib3/connectionpool.py", line 841, in urlopen
    retries = retries.increment(
              ^^^^^^^^^^^^^^^^^^
  File "/home/lucas/airflow_env/lib/python3.12/site-packages/urllib3/util/retry.py", line 449, in increment
    raise reraise(type(error), error, _stacktrace)
          ^^^^^^^^^^^^^^^^^^^^^^^^^^^^^^^^^^^^^^^^
  File "/home/lucas/airflow_env/lib/python3.12/site-packages/urllib3/util/util.py", line 38, in reraise
    raise value.with_traceback(tb)
  File "/home/lucas/airflow_env/lib/python3.12/site-packages/urllib3/connectionpool.py", line 787, in urlopen
    response = self._make_request(
               ^^^^^^^^^^^^^^^^^^^
  File "/home/lucas/airflow_env/lib/python3.12/site-packages/urllib3/connectionpool.py", line 493, in _make_request
    conn.request(
  File "/home/lucas/airflow_env/lib/python3.12/site-packages/urllib3/connection.py", line 459, in request
    self.send(chunk)
  File "/usr/lib/python3.12/http/client.py", line 1055, in send
    self.sock.sendall(data)
  File "/usr/lib/python3.12/ssl.py", line 1211, in sendall
    v = self.send(byte_view[count:])
        ^^^^^^^^^^^^^^^^^^^^^^^^^^^^
  File "/usr/lib/python3.12/ssl.py", line 1180, in send
    return self._sslobj.write(data)
           ^^^^^^^^^^^^^^^^^^^^^^^^
urllib3.exceptions.ProtocolError: ('Connection aborted.', TimeoutError('The write operation timed out'))

The above exception was the direct cause of the following exception:

Traceback (most recent call last):
  File "/home/lucas/airflow_env/lib/python3.12/site-packages/elastic_transport/_transport.py", line 342, in perform_request
    resp = node.perform_request(
           ^^^^^^^^^^^^^^^^^^^^^
  File "/home/lucas/airflow_env/lib/python3.12/site-packages/elastic_transport/_node/_http_urllib3.py", line 202, in perform_request
    raise err from e
elastic_transport.ConnectionError: Connection error caused by: ProtocolError(('Connection aborted.', TimeoutError('The write operation timed out')))
[2025-02-02T21:38:33.311-0300] {_node_pool.py:310} INFO - Resurrected node <Urllib3HttpNode(https://my-elasticsearch-project-a9672d.es.us-east-1.aws.elastic.cloud:443)> (force=False)
[2025-02-02T21:38:43.746-0300] {_transport.py:372} INFO - PUT https://my-elasticsearch-project-a9672d.es.us-east-1.aws.elastic.cloud:443/_bulk [status:N/A duration:10.435s]
[2025-02-02T21:38:43.746-0300] {_node_pool.py:249} WARNING - Node <Urllib3HttpNode(https://my-elasticsearch-project-a9672d.es.us-east-1.aws.elastic.cloud:443)> has failed for 3 times in a row, putting on 4 second timeout
[2025-02-02T21:38:43.746-0300] {_transport.py:415} WARNING - Retrying request after failure (attempt 2 of 3)
Traceback (most recent call last):
  File "/home/lucas/airflow_env/lib/python3.12/site-packages/urllib3/connectionpool.py", line 787, in urlopen
    response = self._make_request(
               ^^^^^^^^^^^^^^^^^^^
  File "/home/lucas/airflow_env/lib/python3.12/site-packages/urllib3/connectionpool.py", line 493, in _make_request
    conn.request(
  File "/home/lucas/airflow_env/lib/python3.12/site-packages/urllib3/connection.py", line 459, in request
    self.send(chunk)
  File "/usr/lib/python3.12/http/client.py", line 1055, in send
    self.sock.sendall(data)
  File "/usr/lib/python3.12/ssl.py", line 1211, in sendall
    v = self.send(byte_view[count:])
        ^^^^^^^^^^^^^^^^^^^^^^^^^^^^
  File "/usr/lib/python3.12/ssl.py", line 1180, in send
    return self._sslobj.write(data)
           ^^^^^^^^^^^^^^^^^^^^^^^^
TimeoutError: The write operation timed out

During handling of the above exception, another exception occurred:

Traceback (most recent call last):
  File "/home/lucas/airflow_env/lib/python3.12/site-packages/elastic_transport/_node/_http_urllib3.py", line 167, in perform_request
    response = self.pool.urlopen(
               ^^^^^^^^^^^^^^^^^^
  File "/home/lucas/airflow_env/lib/python3.12/site-packages/urllib3/connectionpool.py", line 841, in urlopen
    retries = retries.increment(
              ^^^^^^^^^^^^^^^^^^
  File "/home/lucas/airflow_env/lib/python3.12/site-packages/urllib3/util/retry.py", line 449, in increment
    raise reraise(type(error), error, _stacktrace)
          ^^^^^^^^^^^^^^^^^^^^^^^^^^^^^^^^^^^^^^^^
  File "/home/lucas/airflow_env/lib/python3.12/site-packages/urllib3/util/util.py", line 38, in reraise
    raise value.with_traceback(tb)
  File "/home/lucas/airflow_env/lib/python3.12/site-packages/urllib3/connectionpool.py", line 787, in urlopen
    response = self._make_request(
               ^^^^^^^^^^^^^^^^^^^
  File "/home/lucas/airflow_env/lib/python3.12/site-packages/urllib3/connectionpool.py", line 493, in _make_request
    conn.request(
  File "/home/lucas/airflow_env/lib/python3.12/site-packages/urllib3/connection.py", line 459, in request
    self.send(chunk)
  File "/usr/lib/python3.12/http/client.py", line 1055, in send
    self.sock.sendall(data)
  File "/usr/lib/python3.12/ssl.py", line 1211, in sendall
    v = self.send(byte_view[count:])
        ^^^^^^^^^^^^^^^^^^^^^^^^^^^^
  File "/usr/lib/python3.12/ssl.py", line 1180, in send
    return self._sslobj.write(data)
           ^^^^^^^^^^^^^^^^^^^^^^^^
urllib3.exceptions.ProtocolError: ('Connection aborted.', TimeoutError('The write operation timed out'))

The above exception was the direct cause of the following exception:

Traceback (most recent call last):
  File "/home/lucas/airflow_env/lib/python3.12/site-packages/elastic_transport/_transport.py", line 342, in perform_request
    resp = node.perform_request(
           ^^^^^^^^^^^^^^^^^^^^^
  File "/home/lucas/airflow_env/lib/python3.12/site-packages/elastic_transport/_node/_http_urllib3.py", line 202, in perform_request
    raise err from e
elastic_transport.ConnectionError: Connection error caused by: ProtocolError(('Connection aborted.', TimeoutError('The write operation timed out')))
[2025-02-02T21:38:43.748-0300] {_node_pool.py:310} INFO - Resurrected node <Urllib3HttpNode(https://my-elasticsearch-project-a9672d.es.us-east-1.aws.elastic.cloud:443)> (force=False)
[2025-02-02T21:38:54.069-0300] {_transport.py:372} INFO - PUT https://my-elasticsearch-project-a9672d.es.us-east-1.aws.elastic.cloud:443/_bulk [status:N/A duration:10.320s]
[2025-02-02T21:38:54.069-0300] {_node_pool.py:249} WARNING - Node <Urllib3HttpNode(https://my-elasticsearch-project-a9672d.es.us-east-1.aws.elastic.cloud:443)> has failed for 4 times in a row, putting on 8 second timeout
[2025-02-02T21:38:54.070-0300] {taskinstance.py:3311} ERROR - Task failed with exception
Traceback (most recent call last):
  File "/home/lucas/airflow_env/lib/python3.12/site-packages/urllib3/connectionpool.py", line 787, in urlopen
    response = self._make_request(
               ^^^^^^^^^^^^^^^^^^^
  File "/home/lucas/airflow_env/lib/python3.12/site-packages/urllib3/connectionpool.py", line 493, in _make_request
    conn.request(
  File "/home/lucas/airflow_env/lib/python3.12/site-packages/urllib3/connection.py", line 459, in request
    self.send(chunk)
  File "/usr/lib/python3.12/http/client.py", line 1055, in send
    self.sock.sendall(data)
  File "/usr/lib/python3.12/ssl.py", line 1211, in sendall
    v = self.send(byte_view[count:])
        ^^^^^^^^^^^^^^^^^^^^^^^^^^^^
  File "/usr/lib/python3.12/ssl.py", line 1180, in send
    return self._sslobj.write(data)
           ^^^^^^^^^^^^^^^^^^^^^^^^
TimeoutError: The write operation timed out

During handling of the above exception, another exception occurred:

Traceback (most recent call last):
  File "/home/lucas/airflow_env/lib/python3.12/site-packages/elastic_transport/_node/_http_urllib3.py", line 167, in perform_request
    response = self.pool.urlopen(
               ^^^^^^^^^^^^^^^^^^
  File "/home/lucas/airflow_env/lib/python3.12/site-packages/urllib3/connectionpool.py", line 841, in urlopen
    retries = retries.increment(
              ^^^^^^^^^^^^^^^^^^
  File "/home/lucas/airflow_env/lib/python3.12/site-packages/urllib3/util/retry.py", line 449, in increment
    raise reraise(type(error), error, _stacktrace)
          ^^^^^^^^^^^^^^^^^^^^^^^^^^^^^^^^^^^^^^^^
  File "/home/lucas/airflow_env/lib/python3.12/site-packages/urllib3/util/util.py", line 38, in reraise
    raise value.with_traceback(tb)
  File "/home/lucas/airflow_env/lib/python3.12/site-packages/urllib3/connectionpool.py", line 787, in urlopen
    response = self._make_request(
               ^^^^^^^^^^^^^^^^^^^
  File "/home/lucas/airflow_env/lib/python3.12/site-packages/urllib3/connectionpool.py", line 493, in _make_request
    conn.request(
  File "/home/lucas/airflow_env/lib/python3.12/site-packages/urllib3/connection.py", line 459, in request
    self.send(chunk)
  File "/usr/lib/python3.12/http/client.py", line 1055, in send
    self.sock.sendall(data)
  File "/usr/lib/python3.12/ssl.py", line 1211, in sendall
    v = self.send(byte_view[count:])
        ^^^^^^^^^^^^^^^^^^^^^^^^^^^^
  File "/usr/lib/python3.12/ssl.py", line 1180, in send
    return self._sslobj.write(data)
           ^^^^^^^^^^^^^^^^^^^^^^^^
urllib3.exceptions.ProtocolError: ('Connection aborted.', TimeoutError('The write operation timed out'))

The above exception was the direct cause of the following exception:

Traceback (most recent call last):
  File "/home/lucas/airflow_env/lib/python3.12/site-packages/airflow/models/taskinstance.py", line 767, in _execute_task
    result = _execute_callable(context=context, **execute_callable_kwargs)
             ^^^^^^^^^^^^^^^^^^^^^^^^^^^^^^^^^^^^^^^^^^^^^^^^^^^^^^^^^^^^^
  File "/home/lucas/airflow_env/lib/python3.12/site-packages/airflow/models/taskinstance.py", line 733, in _execute_callable
    return ExecutionCallableRunner(
           ^^^^^^^^^^^^^^^^^^^^^^^^
  File "/home/lucas/airflow_env/lib/python3.12/site-packages/airflow/utils/operator_helpers.py", line 252, in run
    return self.func(*args, **kwargs)
           ^^^^^^^^^^^^^^^^^^^^^^^^^^
  File "/home/lucas/airflow_env/lib/python3.12/site-packages/airflow/models/baseoperator.py", line 422, in wrapper
    return func(self, *args, **kwargs)
           ^^^^^^^^^^^^^^^^^^^^^^^^^^^
  File "/home/lucas/airflow_env/lib/python3.12/site-packages/airflow/operators/python.py", line 238, in execute
    return_value = self.execute_callable()
                   ^^^^^^^^^^^^^^^^^^^^^^^
  File "/home/lucas/airflow_env/lib/python3.12/site-packages/airflow/operators/python.py", line 256, in execute_callable
    return runner.run(*self.op_args, **self.op_kwargs)
           ^^^^^^^^^^^^^^^^^^^^^^^^^^^^^^^^^^^^^^^^^^^
  File "/home/lucas/airflow_env/lib/python3.12/site-packages/airflow/utils/operator_helpers.py", line 252, in run
    return self.func(*args, **kwargs)
           ^^^^^^^^^^^^^^^^^^^^^^^^^^
  File "/home/lucas/airflow/dags/DAGInjectPACTRATXAGENDElastic.py", line 158, in inject_data_into_es
    resp = es_client.bulk(
           ^^^^^^^^^^^^^^^
  File "/home/lucas/airflow_env/lib/python3.12/site-packages/elasticsearch/_sync/client/utils.py", line 455, in wrapped
    return api(*args, **kwargs)
           ^^^^^^^^^^^^^^^^^^^^
  File "/home/lucas/airflow_env/lib/python3.12/site-packages/elasticsearch/_sync/client/__init__.py", line 816, in bulk
    return self.perform_request(  # type: ignore[return-value]
           ^^^^^^^^^^^^^^^^^^^^^^^^^^^^^^^^^^^^^^^^^^^^^^^^^^^
  File "/home/lucas/airflow_env/lib/python3.12/site-packages/elasticsearch/_sync/client/_base.py", line 271, in perform_request
    response = self._perform_request(
               ^^^^^^^^^^^^^^^^^^^^^^
  File "/home/lucas/airflow_env/lib/python3.12/site-packages/elasticsearch/_sync/client/_base.py", line 316, in _perform_request
    meta, resp_body = self.transport.perform_request(
                      ^^^^^^^^^^^^^^^^^^^^^^^^^^^^^^^
  File "/home/lucas/airflow_env/lib/python3.12/site-packages/elastic_transport/_transport.py", line 342, in perform_request
    resp = node.perform_request(
           ^^^^^^^^^^^^^^^^^^^^^
  File "/home/lucas/airflow_env/lib/python3.12/site-packages/elastic_transport/_node/_http_urllib3.py", line 202, in perform_request
    raise err from e
elastic_transport.ConnectionError: Connection error caused by: ConnectionError(Connection error caused by: ProtocolError(('Connection aborted.', TimeoutError('The write operation timed out'))))
[2025-02-02T21:38:54.079-0300] {taskinstance.py:1225} INFO - Marking task as FAILED. dag_id=InsertPACTRATxAGENDIntoElastic, task_id=inject_pactrat_agend_into_es, run_id=scheduled__2021-12-04T00:00:00+00:00, execution_date=20211204T000000, start_date=20250203T003806, end_date=20250203T003854
[2025-02-02T21:38:54.089-0300] {taskinstance.py:340} INFO - ::group::Post task execution logs
[2025-02-02T21:38:54.089-0300] {standard_task_runner.py:124} ERROR - Failed to execute job 8324 for task inject_pactrat_agend_into_es (Connection error caused by: ConnectionError(Connection error caused by: ProtocolError(('Connection aborted.', TimeoutError('The write operation timed out')))); 27532)
Traceback (most recent call last):
  File "/home/lucas/airflow_env/lib/python3.12/site-packages/urllib3/connectionpool.py", line 787, in urlopen
    response = self._make_request(
               ^^^^^^^^^^^^^^^^^^^
  File "/home/lucas/airflow_env/lib/python3.12/site-packages/urllib3/connectionpool.py", line 493, in _make_request
    conn.request(
  File "/home/lucas/airflow_env/lib/python3.12/site-packages/urllib3/connection.py", line 459, in request
    self.send(chunk)
  File "/usr/lib/python3.12/http/client.py", line 1055, in send
    self.sock.sendall(data)
  File "/usr/lib/python3.12/ssl.py", line 1211, in sendall
    v = self.send(byte_view[count:])
        ^^^^^^^^^^^^^^^^^^^^^^^^^^^^
  File "/usr/lib/python3.12/ssl.py", line 1180, in send
    return self._sslobj.write(data)
           ^^^^^^^^^^^^^^^^^^^^^^^^
TimeoutError: The write operation timed out

During handling of the above exception, another exception occurred:

Traceback (most recent call last):
  File "/home/lucas/airflow_env/lib/python3.12/site-packages/elastic_transport/_node/_http_urllib3.py", line 167, in perform_request
    response = self.pool.urlopen(
               ^^^^^^^^^^^^^^^^^^
  File "/home/lucas/airflow_env/lib/python3.12/site-packages/urllib3/connectionpool.py", line 841, in urlopen
    retries = retries.increment(
              ^^^^^^^^^^^^^^^^^^
  File "/home/lucas/airflow_env/lib/python3.12/site-packages/urllib3/util/retry.py", line 449, in increment
    raise reraise(type(error), error, _stacktrace)
          ^^^^^^^^^^^^^^^^^^^^^^^^^^^^^^^^^^^^^^^^
  File "/home/lucas/airflow_env/lib/python3.12/site-packages/urllib3/util/util.py", line 38, in reraise
    raise value.with_traceback(tb)
  File "/home/lucas/airflow_env/lib/python3.12/site-packages/urllib3/connectionpool.py", line 787, in urlopen
    response = self._make_request(
               ^^^^^^^^^^^^^^^^^^^
  File "/home/lucas/airflow_env/lib/python3.12/site-packages/urllib3/connectionpool.py", line 493, in _make_request
    conn.request(
  File "/home/lucas/airflow_env/lib/python3.12/site-packages/urllib3/connection.py", line 459, in request
    self.send(chunk)
  File "/usr/lib/python3.12/http/client.py", line 1055, in send
    self.sock.sendall(data)
  File "/usr/lib/python3.12/ssl.py", line 1211, in sendall
    v = self.send(byte_view[count:])
        ^^^^^^^^^^^^^^^^^^^^^^^^^^^^
  File "/usr/lib/python3.12/ssl.py", line 1180, in send
    return self._sslobj.write(data)
           ^^^^^^^^^^^^^^^^^^^^^^^^
urllib3.exceptions.ProtocolError: ('Connection aborted.', TimeoutError('The write operation timed out'))

The above exception was the direct cause of the following exception:

Traceback (most recent call last):
  File "/home/lucas/airflow_env/lib/python3.12/site-packages/airflow/task/task_runner/standard_task_runner.py", line 117, in _start_by_fork
    ret = args.func(args, dag=self.dag)
          ^^^^^^^^^^^^^^^^^^^^^^^^^^^^^
  File "/home/lucas/airflow_env/lib/python3.12/site-packages/airflow/cli/cli_config.py", line 49, in command
    return func(*args, **kwargs)
           ^^^^^^^^^^^^^^^^^^^^^
  File "/home/lucas/airflow_env/lib/python3.12/site-packages/airflow/utils/cli.py", line 116, in wrapper
    return f(*args, **kwargs)
           ^^^^^^^^^^^^^^^^^^
  File "/home/lucas/airflow_env/lib/python3.12/site-packages/airflow/cli/commands/task_command.py", line 483, in task_run
    task_return_code = _run_task_by_selected_method(args, _dag, ti)
                       ^^^^^^^^^^^^^^^^^^^^^^^^^^^^^^^^^^^^^^^^^^^^
  File "/home/lucas/airflow_env/lib/python3.12/site-packages/airflow/cli/commands/task_command.py", line 256, in _run_task_by_selected_method
    return _run_raw_task(args, ti)
           ^^^^^^^^^^^^^^^^^^^^^^^
  File "/home/lucas/airflow_env/lib/python3.12/site-packages/airflow/cli/commands/task_command.py", line 341, in _run_raw_task
    return ti._run_raw_task(
           ^^^^^^^^^^^^^^^^^
  File "/home/lucas/airflow_env/lib/python3.12/site-packages/airflow/utils/session.py", line 97, in wrapper
    return func(*args, session=session, **kwargs)
           ^^^^^^^^^^^^^^^^^^^^^^^^^^^^^^^^^^^^^^
  File "/home/lucas/airflow_env/lib/python3.12/site-packages/airflow/models/taskinstance.py", line 3005, in _run_raw_task
    return _run_raw_task(
           ^^^^^^^^^^^^^^
  File "/home/lucas/airflow_env/lib/python3.12/site-packages/airflow/models/taskinstance.py", line 273, in _run_raw_task
    TaskInstance._execute_task_with_callbacks(
  File "/home/lucas/airflow_env/lib/python3.12/site-packages/airflow/models/taskinstance.py", line 3159, in _execute_task_with_callbacks
    result = self._execute_task(context, task_orig)
             ^^^^^^^^^^^^^^^^^^^^^^^^^^^^^^^^^^^^^^
  File "/home/lucas/airflow_env/lib/python3.12/site-packages/airflow/models/taskinstance.py", line 3183, in _execute_task
    return _execute_task(self, context, task_orig)
           ^^^^^^^^^^^^^^^^^^^^^^^^^^^^^^^^^^^^^^^
  File "/home/lucas/airflow_env/lib/python3.12/site-packages/airflow/models/taskinstance.py", line 767, in _execute_task
    result = _execute_callable(context=context, **execute_callable_kwargs)
             ^^^^^^^^^^^^^^^^^^^^^^^^^^^^^^^^^^^^^^^^^^^^^^^^^^^^^^^^^^^^^
  File "/home/lucas/airflow_env/lib/python3.12/site-packages/airflow/models/taskinstance.py", line 733, in _execute_callable
    return ExecutionCallableRunner(
           ^^^^^^^^^^^^^^^^^^^^^^^^
  File "/home/lucas/airflow_env/lib/python3.12/site-packages/airflow/utils/operator_helpers.py", line 252, in run
    return self.func(*args, **kwargs)
           ^^^^^^^^^^^^^^^^^^^^^^^^^^
  File "/home/lucas/airflow_env/lib/python3.12/site-packages/airflow/models/baseoperator.py", line 422, in wrapper
    return func(self, *args, **kwargs)
           ^^^^^^^^^^^^^^^^^^^^^^^^^^^
  File "/home/lucas/airflow_env/lib/python3.12/site-packages/airflow/operators/python.py", line 238, in execute
    return_value = self.execute_callable()
                   ^^^^^^^^^^^^^^^^^^^^^^^
  File "/home/lucas/airflow_env/lib/python3.12/site-packages/airflow/operators/python.py", line 256, in execute_callable
    return runner.run(*self.op_args, **self.op_kwargs)
           ^^^^^^^^^^^^^^^^^^^^^^^^^^^^^^^^^^^^^^^^^^^
  File "/home/lucas/airflow_env/lib/python3.12/site-packages/airflow/utils/operator_helpers.py", line 252, in run
    return self.func(*args, **kwargs)
           ^^^^^^^^^^^^^^^^^^^^^^^^^^
  File "/home/lucas/airflow/dags/DAGInjectPACTRATXAGENDElastic.py", line 158, in inject_data_into_es
    resp = es_client.bulk(
           ^^^^^^^^^^^^^^^
  File "/home/lucas/airflow_env/lib/python3.12/site-packages/elasticsearch/_sync/client/utils.py", line 455, in wrapped
    return api(*args, **kwargs)
           ^^^^^^^^^^^^^^^^^^^^
  File "/home/lucas/airflow_env/lib/python3.12/site-packages/elasticsearch/_sync/client/__init__.py", line 816, in bulk
    return self.perform_request(  # type: ignore[return-value]
           ^^^^^^^^^^^^^^^^^^^^^^^^^^^^^^^^^^^^^^^^^^^^^^^^^^^
  File "/home/lucas/airflow_env/lib/python3.12/site-packages/elasticsearch/_sync/client/_base.py", line 271, in perform_request
    response = self._perform_request(
               ^^^^^^^^^^^^^^^^^^^^^^
  File "/home/lucas/airflow_env/lib/python3.12/site-packages/elasticsearch/_sync/client/_base.py", line 316, in _perform_request
    meta, resp_body = self.transport.perform_request(
                      ^^^^^^^^^^^^^^^^^^^^^^^^^^^^^^^
  File "/home/lucas/airflow_env/lib/python3.12/site-packages/elastic_transport/_transport.py", line 342, in perform_request
    resp = node.perform_request(
           ^^^^^^^^^^^^^^^^^^^^^
  File "/home/lucas/airflow_env/lib/python3.12/site-packages/elastic_transport/_node/_http_urllib3.py", line 202, in perform_request
    raise err from e
elastic_transport.ConnectionError: Connection error caused by: ConnectionError(Connection error caused by: ProtocolError(('Connection aborted.', TimeoutError('The write operation timed out'))))
[2025-02-02T21:38:54.126-0300] {local_task_job_runner.py:266} INFO - Task exited with return code 1
[2025-02-02T21:38:54.139-0300] {taskinstance.py:3895} INFO - 0 downstream tasks scheduled from follow-on schedule check
[2025-02-02T21:38:54.139-0300] {local_task_job_runner.py:245} INFO - ::endgroup::
