[2025-01-27T20:02:12.484-0300] {local_task_job_runner.py:123} INFO - ::group::Pre task execution logs
[2025-01-27T20:02:12.491-0300] {taskinstance.py:2613} INFO - Dependencies all met for dep_context=non-requeueable deps ti=<TaskInstance: InsertPACTRATxAGENDIntoElastic.inject_pactrat_agend_into_es scheduled__2020-07-04T00:00:00+00:00 [queued]>
[2025-01-27T20:02:12.496-0300] {taskinstance.py:2613} INFO - Dependencies all met for dep_context=requeueable deps ti=<TaskInstance: InsertPACTRATxAGENDIntoElastic.inject_pactrat_agend_into_es scheduled__2020-07-04T00:00:00+00:00 [queued]>
[2025-01-27T20:02:12.496-0300] {taskinstance.py:2866} INFO - Starting attempt 1 of 2
[2025-01-27T20:02:12.507-0300] {taskinstance.py:2889} INFO - Executing <Task(PythonOperator): inject_pactrat_agend_into_es> on 2020-07-04 00:00:00+00:00
[2025-01-27T20:02:12.512-0300] {standard_task_runner.py:72} INFO - Started process 19328 to run task
[2025-01-27T20:02:12.516-0300] {standard_task_runner.py:104} INFO - Running: ['airflow', 'tasks', 'run', 'InsertPACTRATxAGENDIntoElastic', 'inject_pactrat_agend_into_es', 'scheduled__2020-07-04T00:00:00+00:00', '--job-id', '6944', '--raw', '--subdir', 'DAGS_FOLDER/DAGInjectPACTRATXAGENDElastic.py', '--cfg-path', '/tmp/tmphmgs23a3']
[2025-01-27T20:02:12.518-0300] {standard_task_runner.py:105} INFO - Job 6944: Subtask inject_pactrat_agend_into_es
[2025-01-27T20:02:12.555-0300] {task_command.py:467} INFO - Running <TaskInstance: InsertPACTRATxAGENDIntoElastic.inject_pactrat_agend_into_es scheduled__2020-07-04T00:00:00+00:00 [running]> on host lucas-Aspire-A514-54
[2025-01-27T20:02:12.615-0300] {taskinstance.py:3132} INFO - Exporting env vars: AIRFLOW_CTX_DAG_OWNER='lucas' AIRFLOW_CTX_DAG_ID='InsertPACTRATxAGENDIntoElastic' AIRFLOW_CTX_TASK_ID='inject_pactrat_agend_into_es' AIRFLOW_CTX_EXECUTION_DATE='2020-07-04T00:00:00+00:00' AIRFLOW_CTX_TRY_NUMBER='1' AIRFLOW_CTX_DAG_RUN_ID='scheduled__2020-07-04T00:00:00+00:00'
[2025-01-27T20:02:12.616-0300] {taskinstance.py:731} INFO - ::endgroup::
[2025-01-27T20:02:13.029-0300] {logging_mixin.py:190} WARNING - /home/lucas/airflow/dags/DAGInjectPACTRATXAGENDElastic.py:136 DtypeWarning: Columns (2) have mixed types. Specify dtype option on import or set low_memory=False.
[2025-01-27T20:02:13.257-0300] {_transport.py:372} INFO - DELETE http://localhost:9200/pacientes_agendamento [status:N/A duration:0.001s]
[2025-01-27T20:02:13.258-0300] {_node_pool.py:249} WARNING - Node <Urllib3HttpNode(http://localhost:9200)> has failed for 1 times in a row, putting on 1 second timeout
[2025-01-27T20:02:13.258-0300] {_transport.py:415} WARNING - Retrying request after failure (attempt 0 of 3)
Traceback (most recent call last):
  File "/home/lucas/airflow_env/lib/python3.12/site-packages/urllib3/connection.py", line 198, in _new_conn
    sock = connection.create_connection(
           ^^^^^^^^^^^^^^^^^^^^^^^^^^^^^
  File "/home/lucas/airflow_env/lib/python3.12/site-packages/urllib3/util/connection.py", line 85, in create_connection
    raise err
  File "/home/lucas/airflow_env/lib/python3.12/site-packages/urllib3/util/connection.py", line 73, in create_connection
    sock.connect(sa)
ConnectionRefusedError: [Errno 111] Connection refused

The above exception was the direct cause of the following exception:

Traceback (most recent call last):
  File "/home/lucas/airflow_env/lib/python3.12/site-packages/elastic_transport/_node/_http_urllib3.py", line 167, in perform_request
    response = self.pool.urlopen(
               ^^^^^^^^^^^^^^^^^^
  File "/home/lucas/airflow_env/lib/python3.12/site-packages/urllib3/connectionpool.py", line 841, in urlopen
    retries = retries.increment(
              ^^^^^^^^^^^^^^^^^^
  File "/home/lucas/airflow_env/lib/python3.12/site-packages/urllib3/util/retry.py", line 449, in increment
    raise reraise(type(error), error, _stacktrace)
          ^^^^^^^^^^^^^^^^^^^^^^^^^^^^^^^^^^^^^^^^
  File "/home/lucas/airflow_env/lib/python3.12/site-packages/urllib3/util/util.py", line 39, in reraise
    raise value
  File "/home/lucas/airflow_env/lib/python3.12/site-packages/urllib3/connectionpool.py", line 787, in urlopen
    response = self._make_request(
               ^^^^^^^^^^^^^^^^^^^
  File "/home/lucas/airflow_env/lib/python3.12/site-packages/urllib3/connectionpool.py", line 493, in _make_request
    conn.request(
  File "/home/lucas/airflow_env/lib/python3.12/site-packages/urllib3/connection.py", line 445, in request
    self.endheaders()
  File "/usr/lib/python3.12/http/client.py", line 1331, in endheaders
    self._send_output(message_body, encode_chunked=encode_chunked)
  File "/usr/lib/python3.12/http/client.py", line 1091, in _send_output
    self.send(msg)
  File "/usr/lib/python3.12/http/client.py", line 1035, in send
    self.connect()
  File "/home/lucas/airflow_env/lib/python3.12/site-packages/urllib3/connection.py", line 276, in connect
    self.sock = self._new_conn()
                ^^^^^^^^^^^^^^^^
  File "/home/lucas/airflow_env/lib/python3.12/site-packages/urllib3/connection.py", line 213, in _new_conn
    raise NewConnectionError(
urllib3.exceptions.NewConnectionError: <urllib3.connection.HTTPConnection object at 0x743fe197e390>: Failed to establish a new connection: [Errno 111] Connection refused

The above exception was the direct cause of the following exception:

Traceback (most recent call last):
  File "/home/lucas/airflow_env/lib/python3.12/site-packages/elastic_transport/_transport.py", line 342, in perform_request
    resp = node.perform_request(
           ^^^^^^^^^^^^^^^^^^^^^
  File "/home/lucas/airflow_env/lib/python3.12/site-packages/elastic_transport/_node/_http_urllib3.py", line 202, in perform_request
    raise err from e
elastic_transport.ConnectionError: Connection error caused by: NewConnectionError(<urllib3.connection.HTTPConnection object at 0x743fe197e390>: Failed to establish a new connection: [Errno 111] Connection refused)
[2025-01-27T20:02:13.261-0300] {_transport.py:372} INFO - DELETE http://localhost:9200/pacientes_agendamento [status:N/A duration:0.000s]
[2025-01-27T20:02:13.261-0300] {_node_pool.py:249} WARNING - Node <Urllib3HttpNode(http://localhost:9200)> has failed for 2 times in a row, putting on 2 second timeout
[2025-01-27T20:02:13.261-0300] {_transport.py:415} WARNING - Retrying request after failure (attempt 1 of 3)
Traceback (most recent call last):
  File "/home/lucas/airflow_env/lib/python3.12/site-packages/urllib3/connection.py", line 198, in _new_conn
    sock = connection.create_connection(
           ^^^^^^^^^^^^^^^^^^^^^^^^^^^^^
  File "/home/lucas/airflow_env/lib/python3.12/site-packages/urllib3/util/connection.py", line 85, in create_connection
    raise err
  File "/home/lucas/airflow_env/lib/python3.12/site-packages/urllib3/util/connection.py", line 73, in create_connection
    sock.connect(sa)
ConnectionRefusedError: [Errno 111] Connection refused

The above exception was the direct cause of the following exception:

Traceback (most recent call last):
  File "/home/lucas/airflow_env/lib/python3.12/site-packages/elastic_transport/_node/_http_urllib3.py", line 167, in perform_request
    response = self.pool.urlopen(
               ^^^^^^^^^^^^^^^^^^
  File "/home/lucas/airflow_env/lib/python3.12/site-packages/urllib3/connectionpool.py", line 841, in urlopen
    retries = retries.increment(
              ^^^^^^^^^^^^^^^^^^
  File "/home/lucas/airflow_env/lib/python3.12/site-packages/urllib3/util/retry.py", line 449, in increment
    raise reraise(type(error), error, _stacktrace)
          ^^^^^^^^^^^^^^^^^^^^^^^^^^^^^^^^^^^^^^^^
  File "/home/lucas/airflow_env/lib/python3.12/site-packages/urllib3/util/util.py", line 39, in reraise
    raise value
  File "/home/lucas/airflow_env/lib/python3.12/site-packages/urllib3/connectionpool.py", line 787, in urlopen
    response = self._make_request(
               ^^^^^^^^^^^^^^^^^^^
  File "/home/lucas/airflow_env/lib/python3.12/site-packages/urllib3/connectionpool.py", line 493, in _make_request
    conn.request(
  File "/home/lucas/airflow_env/lib/python3.12/site-packages/urllib3/connection.py", line 445, in request
    self.endheaders()
  File "/usr/lib/python3.12/http/client.py", line 1331, in endheaders
    self._send_output(message_body, encode_chunked=encode_chunked)
  File "/usr/lib/python3.12/http/client.py", line 1091, in _send_output
    self.send(msg)
  File "/usr/lib/python3.12/http/client.py", line 1035, in send
    self.connect()
  File "/home/lucas/airflow_env/lib/python3.12/site-packages/urllib3/connection.py", line 276, in connect
    self.sock = self._new_conn()
                ^^^^^^^^^^^^^^^^
  File "/home/lucas/airflow_env/lib/python3.12/site-packages/urllib3/connection.py", line 213, in _new_conn
    raise NewConnectionError(
urllib3.exceptions.NewConnectionError: <urllib3.connection.HTTPConnection object at 0x743fe197e7b0>: Failed to establish a new connection: [Errno 111] Connection refused

The above exception was the direct cause of the following exception:

Traceback (most recent call last):
  File "/home/lucas/airflow_env/lib/python3.12/site-packages/elastic_transport/_transport.py", line 342, in perform_request
    resp = node.perform_request(
           ^^^^^^^^^^^^^^^^^^^^^
  File "/home/lucas/airflow_env/lib/python3.12/site-packages/elastic_transport/_node/_http_urllib3.py", line 202, in perform_request
    raise err from e
elastic_transport.ConnectionError: Connection error caused by: NewConnectionError(<urllib3.connection.HTTPConnection object at 0x743fe197e7b0>: Failed to establish a new connection: [Errno 111] Connection refused)
[2025-01-27T20:02:13.262-0300] {_transport.py:372} INFO - DELETE http://localhost:9200/pacientes_agendamento [status:N/A duration:0.000s]
[2025-01-27T20:02:13.262-0300] {_node_pool.py:249} WARNING - Node <Urllib3HttpNode(http://localhost:9200)> has failed for 3 times in a row, putting on 4 second timeout
[2025-01-27T20:02:13.263-0300] {_transport.py:415} WARNING - Retrying request after failure (attempt 2 of 3)
Traceback (most recent call last):
  File "/home/lucas/airflow_env/lib/python3.12/site-packages/urllib3/connection.py", line 198, in _new_conn
    sock = connection.create_connection(
           ^^^^^^^^^^^^^^^^^^^^^^^^^^^^^
  File "/home/lucas/airflow_env/lib/python3.12/site-packages/urllib3/util/connection.py", line 85, in create_connection
    raise err
  File "/home/lucas/airflow_env/lib/python3.12/site-packages/urllib3/util/connection.py", line 73, in create_connection
    sock.connect(sa)
ConnectionRefusedError: [Errno 111] Connection refused

The above exception was the direct cause of the following exception:

Traceback (most recent call last):
  File "/home/lucas/airflow_env/lib/python3.12/site-packages/elastic_transport/_node/_http_urllib3.py", line 167, in perform_request
    response = self.pool.urlopen(
               ^^^^^^^^^^^^^^^^^^
  File "/home/lucas/airflow_env/lib/python3.12/site-packages/urllib3/connectionpool.py", line 841, in urlopen
    retries = retries.increment(
              ^^^^^^^^^^^^^^^^^^
  File "/home/lucas/airflow_env/lib/python3.12/site-packages/urllib3/util/retry.py", line 449, in increment
    raise reraise(type(error), error, _stacktrace)
          ^^^^^^^^^^^^^^^^^^^^^^^^^^^^^^^^^^^^^^^^
  File "/home/lucas/airflow_env/lib/python3.12/site-packages/urllib3/util/util.py", line 39, in reraise
    raise value
  File "/home/lucas/airflow_env/lib/python3.12/site-packages/urllib3/connectionpool.py", line 787, in urlopen
    response = self._make_request(
               ^^^^^^^^^^^^^^^^^^^
  File "/home/lucas/airflow_env/lib/python3.12/site-packages/urllib3/connectionpool.py", line 493, in _make_request
    conn.request(
  File "/home/lucas/airflow_env/lib/python3.12/site-packages/urllib3/connection.py", line 445, in request
    self.endheaders()
  File "/usr/lib/python3.12/http/client.py", line 1331, in endheaders
    self._send_output(message_body, encode_chunked=encode_chunked)
  File "/usr/lib/python3.12/http/client.py", line 1091, in _send_output
    self.send(msg)
  File "/usr/lib/python3.12/http/client.py", line 1035, in send
    self.connect()
  File "/home/lucas/airflow_env/lib/python3.12/site-packages/urllib3/connection.py", line 276, in connect
    self.sock = self._new_conn()
                ^^^^^^^^^^^^^^^^
  File "/home/lucas/airflow_env/lib/python3.12/site-packages/urllib3/connection.py", line 213, in _new_conn
    raise NewConnectionError(
urllib3.exceptions.NewConnectionError: <urllib3.connection.HTTPConnection object at 0x743fe197f650>: Failed to establish a new connection: [Errno 111] Connection refused

The above exception was the direct cause of the following exception:

Traceback (most recent call last):
  File "/home/lucas/airflow_env/lib/python3.12/site-packages/elastic_transport/_transport.py", line 342, in perform_request
    resp = node.perform_request(
           ^^^^^^^^^^^^^^^^^^^^^
  File "/home/lucas/airflow_env/lib/python3.12/site-packages/elastic_transport/_node/_http_urllib3.py", line 202, in perform_request
    raise err from e
elastic_transport.ConnectionError: Connection error caused by: NewConnectionError(<urllib3.connection.HTTPConnection object at 0x743fe197f650>: Failed to establish a new connection: [Errno 111] Connection refused)
[2025-01-27T20:02:13.264-0300] {_transport.py:372} INFO - DELETE http://localhost:9200/pacientes_agendamento [status:N/A duration:0.000s]
[2025-01-27T20:02:13.264-0300] {_node_pool.py:249} WARNING - Node <Urllib3HttpNode(http://localhost:9200)> has failed for 4 times in a row, putting on 8 second timeout
[2025-01-27T20:02:13.264-0300] {_transport.py:372} INFO - PUT http://localhost:9200/pacientes_agendamento [status:N/A duration:0.000s]
[2025-01-27T20:02:13.265-0300] {_node_pool.py:249} WARNING - Node <Urllib3HttpNode(http://localhost:9200)> has failed for 5 times in a row, putting on 16 second timeout
[2025-01-27T20:02:13.265-0300] {_transport.py:415} WARNING - Retrying request after failure (attempt 0 of 3)
Traceback (most recent call last):
  File "/home/lucas/airflow_env/lib/python3.12/site-packages/urllib3/connection.py", line 198, in _new_conn
    sock = connection.create_connection(
           ^^^^^^^^^^^^^^^^^^^^^^^^^^^^^
  File "/home/lucas/airflow_env/lib/python3.12/site-packages/urllib3/util/connection.py", line 85, in create_connection
    raise err
  File "/home/lucas/airflow_env/lib/python3.12/site-packages/urllib3/util/connection.py", line 73, in create_connection
    sock.connect(sa)
ConnectionRefusedError: [Errno 111] Connection refused

The above exception was the direct cause of the following exception:

Traceback (most recent call last):
  File "/home/lucas/airflow_env/lib/python3.12/site-packages/elastic_transport/_node/_http_urllib3.py", line 167, in perform_request
    response = self.pool.urlopen(
               ^^^^^^^^^^^^^^^^^^
  File "/home/lucas/airflow_env/lib/python3.12/site-packages/urllib3/connectionpool.py", line 841, in urlopen
    retries = retries.increment(
              ^^^^^^^^^^^^^^^^^^
  File "/home/lucas/airflow_env/lib/python3.12/site-packages/urllib3/util/retry.py", line 449, in increment
    raise reraise(type(error), error, _stacktrace)
          ^^^^^^^^^^^^^^^^^^^^^^^^^^^^^^^^^^^^^^^^
  File "/home/lucas/airflow_env/lib/python3.12/site-packages/urllib3/util/util.py", line 39, in reraise
    raise value
  File "/home/lucas/airflow_env/lib/python3.12/site-packages/urllib3/connectionpool.py", line 787, in urlopen
    response = self._make_request(
               ^^^^^^^^^^^^^^^^^^^
  File "/home/lucas/airflow_env/lib/python3.12/site-packages/urllib3/connectionpool.py", line 493, in _make_request
    conn.request(
  File "/home/lucas/airflow_env/lib/python3.12/site-packages/urllib3/connection.py", line 445, in request
    self.endheaders()
  File "/usr/lib/python3.12/http/client.py", line 1331, in endheaders
    self._send_output(message_body, encode_chunked=encode_chunked)
  File "/usr/lib/python3.12/http/client.py", line 1091, in _send_output
    self.send(msg)
  File "/usr/lib/python3.12/http/client.py", line 1035, in send
    self.connect()
  File "/home/lucas/airflow_env/lib/python3.12/site-packages/urllib3/connection.py", line 276, in connect
    self.sock = self._new_conn()
                ^^^^^^^^^^^^^^^^
  File "/home/lucas/airflow_env/lib/python3.12/site-packages/urllib3/connection.py", line 213, in _new_conn
    raise NewConnectionError(
urllib3.exceptions.NewConnectionError: <urllib3.connection.HTTPConnection object at 0x743fe18e4560>: Failed to establish a new connection: [Errno 111] Connection refused

The above exception was the direct cause of the following exception:

Traceback (most recent call last):
  File "/home/lucas/airflow_env/lib/python3.12/site-packages/elastic_transport/_transport.py", line 342, in perform_request
    resp = node.perform_request(
           ^^^^^^^^^^^^^^^^^^^^^
  File "/home/lucas/airflow_env/lib/python3.12/site-packages/elastic_transport/_node/_http_urllib3.py", line 202, in perform_request
    raise err from e
elastic_transport.ConnectionError: Connection error caused by: NewConnectionError(<urllib3.connection.HTTPConnection object at 0x743fe18e4560>: Failed to establish a new connection: [Errno 111] Connection refused)
[2025-01-27T20:02:13.266-0300] {_transport.py:372} INFO - PUT http://localhost:9200/pacientes_agendamento [status:N/A duration:0.000s]
[2025-01-27T20:02:13.266-0300] {_node_pool.py:249} WARNING - Node <Urllib3HttpNode(http://localhost:9200)> has failed for 6 times in a row, putting on 30 second timeout
[2025-01-27T20:02:13.266-0300] {_transport.py:415} WARNING - Retrying request after failure (attempt 1 of 3)
Traceback (most recent call last):
  File "/home/lucas/airflow_env/lib/python3.12/site-packages/urllib3/connection.py", line 198, in _new_conn
    sock = connection.create_connection(
           ^^^^^^^^^^^^^^^^^^^^^^^^^^^^^
  File "/home/lucas/airflow_env/lib/python3.12/site-packages/urllib3/util/connection.py", line 85, in create_connection
    raise err
  File "/home/lucas/airflow_env/lib/python3.12/site-packages/urllib3/util/connection.py", line 73, in create_connection
    sock.connect(sa)
ConnectionRefusedError: [Errno 111] Connection refused

The above exception was the direct cause of the following exception:

Traceback (most recent call last):
  File "/home/lucas/airflow_env/lib/python3.12/site-packages/elastic_transport/_node/_http_urllib3.py", line 167, in perform_request
    response = self.pool.urlopen(
               ^^^^^^^^^^^^^^^^^^
  File "/home/lucas/airflow_env/lib/python3.12/site-packages/urllib3/connectionpool.py", line 841, in urlopen
    retries = retries.increment(
              ^^^^^^^^^^^^^^^^^^
  File "/home/lucas/airflow_env/lib/python3.12/site-packages/urllib3/util/retry.py", line 449, in increment
    raise reraise(type(error), error, _stacktrace)
          ^^^^^^^^^^^^^^^^^^^^^^^^^^^^^^^^^^^^^^^^
  File "/home/lucas/airflow_env/lib/python3.12/site-packages/urllib3/util/util.py", line 39, in reraise
    raise value
  File "/home/lucas/airflow_env/lib/python3.12/site-packages/urllib3/connectionpool.py", line 787, in urlopen
    response = self._make_request(
               ^^^^^^^^^^^^^^^^^^^
  File "/home/lucas/airflow_env/lib/python3.12/site-packages/urllib3/connectionpool.py", line 493, in _make_request
    conn.request(
  File "/home/lucas/airflow_env/lib/python3.12/site-packages/urllib3/connection.py", line 445, in request
    self.endheaders()
  File "/usr/lib/python3.12/http/client.py", line 1331, in endheaders
    self._send_output(message_body, encode_chunked=encode_chunked)
  File "/usr/lib/python3.12/http/client.py", line 1091, in _send_output
    self.send(msg)
  File "/usr/lib/python3.12/http/client.py", line 1035, in send
    self.connect()
  File "/home/lucas/airflow_env/lib/python3.12/site-packages/urllib3/connection.py", line 276, in connect
    self.sock = self._new_conn()
                ^^^^^^^^^^^^^^^^
  File "/home/lucas/airflow_env/lib/python3.12/site-packages/urllib3/connection.py", line 213, in _new_conn
    raise NewConnectionError(
urllib3.exceptions.NewConnectionError: <urllib3.connection.HTTPConnection object at 0x743fe18e4b30>: Failed to establish a new connection: [Errno 111] Connection refused

The above exception was the direct cause of the following exception:

Traceback (most recent call last):
  File "/home/lucas/airflow_env/lib/python3.12/site-packages/elastic_transport/_transport.py", line 342, in perform_request
    resp = node.perform_request(
           ^^^^^^^^^^^^^^^^^^^^^
  File "/home/lucas/airflow_env/lib/python3.12/site-packages/elastic_transport/_node/_http_urllib3.py", line 202, in perform_request
    raise err from e
elastic_transport.ConnectionError: Connection error caused by: NewConnectionError(<urllib3.connection.HTTPConnection object at 0x743fe18e4b30>: Failed to establish a new connection: [Errno 111] Connection refused)
[2025-01-27T20:02:13.268-0300] {_transport.py:372} INFO - PUT http://localhost:9200/pacientes_agendamento [status:N/A duration:0.000s]
[2025-01-27T20:02:13.268-0300] {_node_pool.py:249} WARNING - Node <Urllib3HttpNode(http://localhost:9200)> has failed for 7 times in a row, putting on 30 second timeout
[2025-01-27T20:02:13.268-0300] {_transport.py:415} WARNING - Retrying request after failure (attempt 2 of 3)
Traceback (most recent call last):
  File "/home/lucas/airflow_env/lib/python3.12/site-packages/urllib3/connection.py", line 198, in _new_conn
    sock = connection.create_connection(
           ^^^^^^^^^^^^^^^^^^^^^^^^^^^^^
  File "/home/lucas/airflow_env/lib/python3.12/site-packages/urllib3/util/connection.py", line 85, in create_connection
    raise err
  File "/home/lucas/airflow_env/lib/python3.12/site-packages/urllib3/util/connection.py", line 73, in create_connection
    sock.connect(sa)
ConnectionRefusedError: [Errno 111] Connection refused

The above exception was the direct cause of the following exception:

Traceback (most recent call last):
  File "/home/lucas/airflow_env/lib/python3.12/site-packages/elastic_transport/_node/_http_urllib3.py", line 167, in perform_request
    response = self.pool.urlopen(
               ^^^^^^^^^^^^^^^^^^
  File "/home/lucas/airflow_env/lib/python3.12/site-packages/urllib3/connectionpool.py", line 841, in urlopen
    retries = retries.increment(
              ^^^^^^^^^^^^^^^^^^
  File "/home/lucas/airflow_env/lib/python3.12/site-packages/urllib3/util/retry.py", line 449, in increment
    raise reraise(type(error), error, _stacktrace)
          ^^^^^^^^^^^^^^^^^^^^^^^^^^^^^^^^^^^^^^^^
  File "/home/lucas/airflow_env/lib/python3.12/site-packages/urllib3/util/util.py", line 39, in reraise
    raise value
  File "/home/lucas/airflow_env/lib/python3.12/site-packages/urllib3/connectionpool.py", line 787, in urlopen
    response = self._make_request(
               ^^^^^^^^^^^^^^^^^^^
  File "/home/lucas/airflow_env/lib/python3.12/site-packages/urllib3/connectionpool.py", line 493, in _make_request
    conn.request(
  File "/home/lucas/airflow_env/lib/python3.12/site-packages/urllib3/connection.py", line 445, in request
    self.endheaders()
  File "/usr/lib/python3.12/http/client.py", line 1331, in endheaders
    self._send_output(message_body, encode_chunked=encode_chunked)
  File "/usr/lib/python3.12/http/client.py", line 1091, in _send_output
    self.send(msg)
  File "/usr/lib/python3.12/http/client.py", line 1035, in send
    self.connect()
  File "/home/lucas/airflow_env/lib/python3.12/site-packages/urllib3/connection.py", line 276, in connect
    self.sock = self._new_conn()
                ^^^^^^^^^^^^^^^^
  File "/home/lucas/airflow_env/lib/python3.12/site-packages/urllib3/connection.py", line 213, in _new_conn
    raise NewConnectionError(
urllib3.exceptions.NewConnectionError: <urllib3.connection.HTTPConnection object at 0x743fe18e51c0>: Failed to establish a new connection: [Errno 111] Connection refused

The above exception was the direct cause of the following exception:

Traceback (most recent call last):
  File "/home/lucas/airflow_env/lib/python3.12/site-packages/elastic_transport/_transport.py", line 342, in perform_request
    resp = node.perform_request(
           ^^^^^^^^^^^^^^^^^^^^^
  File "/home/lucas/airflow_env/lib/python3.12/site-packages/elastic_transport/_node/_http_urllib3.py", line 202, in perform_request
    raise err from e
elastic_transport.ConnectionError: Connection error caused by: NewConnectionError(<urllib3.connection.HTTPConnection object at 0x743fe18e51c0>: Failed to establish a new connection: [Errno 111] Connection refused)
[2025-01-27T20:02:13.269-0300] {_transport.py:372} INFO - PUT http://localhost:9200/pacientes_agendamento [status:N/A duration:0.000s]
[2025-01-27T20:02:13.269-0300] {_node_pool.py:249} WARNING - Node <Urllib3HttpNode(http://localhost:9200)> has failed for 8 times in a row, putting on 30 second timeout
[2025-01-27T20:02:13.270-0300] {taskinstance.py:3311} ERROR - Task failed with exception
Traceback (most recent call last):
  File "/home/lucas/airflow_env/lib/python3.12/site-packages/urllib3/connection.py", line 198, in _new_conn
    sock = connection.create_connection(
           ^^^^^^^^^^^^^^^^^^^^^^^^^^^^^
  File "/home/lucas/airflow_env/lib/python3.12/site-packages/urllib3/util/connection.py", line 85, in create_connection
    raise err
  File "/home/lucas/airflow_env/lib/python3.12/site-packages/urllib3/util/connection.py", line 73, in create_connection
    sock.connect(sa)
ConnectionRefusedError: [Errno 111] Connection refused

The above exception was the direct cause of the following exception:

Traceback (most recent call last):
  File "/home/lucas/airflow_env/lib/python3.12/site-packages/elastic_transport/_node/_http_urllib3.py", line 167, in perform_request
    response = self.pool.urlopen(
               ^^^^^^^^^^^^^^^^^^
  File "/home/lucas/airflow_env/lib/python3.12/site-packages/urllib3/connectionpool.py", line 841, in urlopen
    retries = retries.increment(
              ^^^^^^^^^^^^^^^^^^
  File "/home/lucas/airflow_env/lib/python3.12/site-packages/urllib3/util/retry.py", line 449, in increment
    raise reraise(type(error), error, _stacktrace)
          ^^^^^^^^^^^^^^^^^^^^^^^^^^^^^^^^^^^^^^^^
  File "/home/lucas/airflow_env/lib/python3.12/site-packages/urllib3/util/util.py", line 39, in reraise
    raise value
  File "/home/lucas/airflow_env/lib/python3.12/site-packages/urllib3/connectionpool.py", line 787, in urlopen
    response = self._make_request(
               ^^^^^^^^^^^^^^^^^^^
  File "/home/lucas/airflow_env/lib/python3.12/site-packages/urllib3/connectionpool.py", line 493, in _make_request
    conn.request(
  File "/home/lucas/airflow_env/lib/python3.12/site-packages/urllib3/connection.py", line 445, in request
    self.endheaders()
  File "/usr/lib/python3.12/http/client.py", line 1331, in endheaders
    self._send_output(message_body, encode_chunked=encode_chunked)
  File "/usr/lib/python3.12/http/client.py", line 1091, in _send_output
    self.send(msg)
  File "/usr/lib/python3.12/http/client.py", line 1035, in send
    self.connect()
  File "/home/lucas/airflow_env/lib/python3.12/site-packages/urllib3/connection.py", line 276, in connect
    self.sock = self._new_conn()
                ^^^^^^^^^^^^^^^^
  File "/home/lucas/airflow_env/lib/python3.12/site-packages/urllib3/connection.py", line 213, in _new_conn
    raise NewConnectionError(
urllib3.exceptions.NewConnectionError: <urllib3.connection.HTTPConnection object at 0x743fe18e5a60>: Failed to establish a new connection: [Errno 111] Connection refused

The above exception was the direct cause of the following exception:

Traceback (most recent call last):
  File "/home/lucas/airflow_env/lib/python3.12/site-packages/airflow/models/taskinstance.py", line 767, in _execute_task
    result = _execute_callable(context=context, **execute_callable_kwargs)
             ^^^^^^^^^^^^^^^^^^^^^^^^^^^^^^^^^^^^^^^^^^^^^^^^^^^^^^^^^^^^^
  File "/home/lucas/airflow_env/lib/python3.12/site-packages/airflow/models/taskinstance.py", line 733, in _execute_callable
    return ExecutionCallableRunner(
           ^^^^^^^^^^^^^^^^^^^^^^^^
  File "/home/lucas/airflow_env/lib/python3.12/site-packages/airflow/utils/operator_helpers.py", line 252, in run
    return self.func(*args, **kwargs)
           ^^^^^^^^^^^^^^^^^^^^^^^^^^
  File "/home/lucas/airflow_env/lib/python3.12/site-packages/airflow/models/baseoperator.py", line 422, in wrapper
    return func(self, *args, **kwargs)
           ^^^^^^^^^^^^^^^^^^^^^^^^^^^
  File "/home/lucas/airflow_env/lib/python3.12/site-packages/airflow/operators/python.py", line 238, in execute
    return_value = self.execute_callable()
                   ^^^^^^^^^^^^^^^^^^^^^^^
  File "/home/lucas/airflow_env/lib/python3.12/site-packages/airflow/operators/python.py", line 256, in execute_callable
    return runner.run(*self.op_args, **self.op_kwargs)
           ^^^^^^^^^^^^^^^^^^^^^^^^^^^^^^^^^^^^^^^^^^^
  File "/home/lucas/airflow_env/lib/python3.12/site-packages/airflow/utils/operator_helpers.py", line 252, in run
    return self.func(*args, **kwargs)
           ^^^^^^^^^^^^^^^^^^^^^^^^^^
  File "/home/lucas/airflow/dags/DAGInjectPACTRATXAGENDElastic.py", line 148, in inject_data_into_es
    resp = es_client.indices.create(
           ^^^^^^^^^^^^^^^^^^^^^^^^^
  File "/home/lucas/airflow_env/lib/python3.12/site-packages/elasticsearch/_sync/client/utils.py", line 455, in wrapped
    return api(*args, **kwargs)
           ^^^^^^^^^^^^^^^^^^^^
  File "/home/lucas/airflow_env/lib/python3.12/site-packages/elasticsearch/_sync/client/indices.py", line 633, in create
    return self.perform_request(  # type: ignore[return-value]
           ^^^^^^^^^^^^^^^^^^^^^^^^^^^^^^^^^^^^^^^^^^^^^^^^^^^
  File "/home/lucas/airflow_env/lib/python3.12/site-packages/elasticsearch/_sync/client/_base.py", line 423, in perform_request
    return self._client.perform_request(
           ^^^^^^^^^^^^^^^^^^^^^^^^^^^^^
  File "/home/lucas/airflow_env/lib/python3.12/site-packages/elasticsearch/_sync/client/_base.py", line 271, in perform_request
    response = self._perform_request(
               ^^^^^^^^^^^^^^^^^^^^^^
  File "/home/lucas/airflow_env/lib/python3.12/site-packages/elasticsearch/_sync/client/_base.py", line 316, in _perform_request
    meta, resp_body = self.transport.perform_request(
                      ^^^^^^^^^^^^^^^^^^^^^^^^^^^^^^^
  File "/home/lucas/airflow_env/lib/python3.12/site-packages/elastic_transport/_transport.py", line 342, in perform_request
    resp = node.perform_request(
           ^^^^^^^^^^^^^^^^^^^^^
  File "/home/lucas/airflow_env/lib/python3.12/site-packages/elastic_transport/_node/_http_urllib3.py", line 202, in perform_request
    raise err from e
elastic_transport.ConnectionError: Connection error caused by: ConnectionError(Connection error caused by: NewConnectionError(<urllib3.connection.HTTPConnection object at 0x743fe18e4560>: Failed to establish a new connection: [Errno 111] Connection refused))
[2025-01-27T20:02:13.276-0300] {taskinstance.py:1225} INFO - Marking task as UP_FOR_RETRY. dag_id=InsertPACTRATxAGENDIntoElastic, task_id=inject_pactrat_agend_into_es, run_id=scheduled__2020-07-04T00:00:00+00:00, execution_date=20200704T000000, start_date=20250127T230212, end_date=20250127T230213
[2025-01-27T20:02:13.287-0300] {taskinstance.py:340} INFO - ::group::Post task execution logs
[2025-01-27T20:02:13.287-0300] {standard_task_runner.py:124} ERROR - Failed to execute job 6944 for task inject_pactrat_agend_into_es (Connection error caused by: ConnectionError(Connection error caused by: NewConnectionError(<urllib3.connection.HTTPConnection object at 0x743fe18e4560>: Failed to establish a new connection: [Errno 111] Connection refused)); 19328)
Traceback (most recent call last):
  File "/home/lucas/airflow_env/lib/python3.12/site-packages/urllib3/connection.py", line 198, in _new_conn
    sock = connection.create_connection(
           ^^^^^^^^^^^^^^^^^^^^^^^^^^^^^
  File "/home/lucas/airflow_env/lib/python3.12/site-packages/urllib3/util/connection.py", line 85, in create_connection
    raise err
  File "/home/lucas/airflow_env/lib/python3.12/site-packages/urllib3/util/connection.py", line 73, in create_connection
    sock.connect(sa)
ConnectionRefusedError: [Errno 111] Connection refused

The above exception was the direct cause of the following exception:

Traceback (most recent call last):
  File "/home/lucas/airflow_env/lib/python3.12/site-packages/elastic_transport/_node/_http_urllib3.py", line 167, in perform_request
    response = self.pool.urlopen(
               ^^^^^^^^^^^^^^^^^^
  File "/home/lucas/airflow_env/lib/python3.12/site-packages/urllib3/connectionpool.py", line 841, in urlopen
    retries = retries.increment(
              ^^^^^^^^^^^^^^^^^^
  File "/home/lucas/airflow_env/lib/python3.12/site-packages/urllib3/util/retry.py", line 449, in increment
    raise reraise(type(error), error, _stacktrace)
          ^^^^^^^^^^^^^^^^^^^^^^^^^^^^^^^^^^^^^^^^
  File "/home/lucas/airflow_env/lib/python3.12/site-packages/urllib3/util/util.py", line 39, in reraise
    raise value
  File "/home/lucas/airflow_env/lib/python3.12/site-packages/urllib3/connectionpool.py", line 787, in urlopen
    response = self._make_request(
               ^^^^^^^^^^^^^^^^^^^
  File "/home/lucas/airflow_env/lib/python3.12/site-packages/urllib3/connectionpool.py", line 493, in _make_request
    conn.request(
  File "/home/lucas/airflow_env/lib/python3.12/site-packages/urllib3/connection.py", line 445, in request
    self.endheaders()
  File "/usr/lib/python3.12/http/client.py", line 1331, in endheaders
    self._send_output(message_body, encode_chunked=encode_chunked)
  File "/usr/lib/python3.12/http/client.py", line 1091, in _send_output
    self.send(msg)
  File "/usr/lib/python3.12/http/client.py", line 1035, in send
    self.connect()
  File "/home/lucas/airflow_env/lib/python3.12/site-packages/urllib3/connection.py", line 276, in connect
    self.sock = self._new_conn()
                ^^^^^^^^^^^^^^^^
  File "/home/lucas/airflow_env/lib/python3.12/site-packages/urllib3/connection.py", line 213, in _new_conn
    raise NewConnectionError(
urllib3.exceptions.NewConnectionError: <urllib3.connection.HTTPConnection object at 0x743fe18e5a60>: Failed to establish a new connection: [Errno 111] Connection refused

The above exception was the direct cause of the following exception:

Traceback (most recent call last):
  File "/home/lucas/airflow_env/lib/python3.12/site-packages/airflow/task/task_runner/standard_task_runner.py", line 117, in _start_by_fork
    ret = args.func(args, dag=self.dag)
          ^^^^^^^^^^^^^^^^^^^^^^^^^^^^^
  File "/home/lucas/airflow_env/lib/python3.12/site-packages/airflow/cli/cli_config.py", line 49, in command
    return func(*args, **kwargs)
           ^^^^^^^^^^^^^^^^^^^^^
  File "/home/lucas/airflow_env/lib/python3.12/site-packages/airflow/utils/cli.py", line 116, in wrapper
    return f(*args, **kwargs)
           ^^^^^^^^^^^^^^^^^^
  File "/home/lucas/airflow_env/lib/python3.12/site-packages/airflow/cli/commands/task_command.py", line 483, in task_run
    task_return_code = _run_task_by_selected_method(args, _dag, ti)
                       ^^^^^^^^^^^^^^^^^^^^^^^^^^^^^^^^^^^^^^^^^^^^
  File "/home/lucas/airflow_env/lib/python3.12/site-packages/airflow/cli/commands/task_command.py", line 256, in _run_task_by_selected_method
    return _run_raw_task(args, ti)
           ^^^^^^^^^^^^^^^^^^^^^^^
  File "/home/lucas/airflow_env/lib/python3.12/site-packages/airflow/cli/commands/task_command.py", line 341, in _run_raw_task
    return ti._run_raw_task(
           ^^^^^^^^^^^^^^^^^
  File "/home/lucas/airflow_env/lib/python3.12/site-packages/airflow/utils/session.py", line 97, in wrapper
    return func(*args, session=session, **kwargs)
           ^^^^^^^^^^^^^^^^^^^^^^^^^^^^^^^^^^^^^^
  File "/home/lucas/airflow_env/lib/python3.12/site-packages/airflow/models/taskinstance.py", line 3005, in _run_raw_task
    return _run_raw_task(
           ^^^^^^^^^^^^^^
  File "/home/lucas/airflow_env/lib/python3.12/site-packages/airflow/models/taskinstance.py", line 273, in _run_raw_task
    TaskInstance._execute_task_with_callbacks(
  File "/home/lucas/airflow_env/lib/python3.12/site-packages/airflow/models/taskinstance.py", line 3159, in _execute_task_with_callbacks
    result = self._execute_task(context, task_orig)
             ^^^^^^^^^^^^^^^^^^^^^^^^^^^^^^^^^^^^^^
  File "/home/lucas/airflow_env/lib/python3.12/site-packages/airflow/models/taskinstance.py", line 3183, in _execute_task
    return _execute_task(self, context, task_orig)
           ^^^^^^^^^^^^^^^^^^^^^^^^^^^^^^^^^^^^^^^
  File "/home/lucas/airflow_env/lib/python3.12/site-packages/airflow/models/taskinstance.py", line 767, in _execute_task
    result = _execute_callable(context=context, **execute_callable_kwargs)
             ^^^^^^^^^^^^^^^^^^^^^^^^^^^^^^^^^^^^^^^^^^^^^^^^^^^^^^^^^^^^^
  File "/home/lucas/airflow_env/lib/python3.12/site-packages/airflow/models/taskinstance.py", line 733, in _execute_callable
    return ExecutionCallableRunner(
           ^^^^^^^^^^^^^^^^^^^^^^^^
  File "/home/lucas/airflow_env/lib/python3.12/site-packages/airflow/utils/operator_helpers.py", line 252, in run
    return self.func(*args, **kwargs)
           ^^^^^^^^^^^^^^^^^^^^^^^^^^
  File "/home/lucas/airflow_env/lib/python3.12/site-packages/airflow/models/baseoperator.py", line 422, in wrapper
    return func(self, *args, **kwargs)
           ^^^^^^^^^^^^^^^^^^^^^^^^^^^
  File "/home/lucas/airflow_env/lib/python3.12/site-packages/airflow/operators/python.py", line 238, in execute
    return_value = self.execute_callable()
                   ^^^^^^^^^^^^^^^^^^^^^^^
  File "/home/lucas/airflow_env/lib/python3.12/site-packages/airflow/operators/python.py", line 256, in execute_callable
    return runner.run(*self.op_args, **self.op_kwargs)
           ^^^^^^^^^^^^^^^^^^^^^^^^^^^^^^^^^^^^^^^^^^^
  File "/home/lucas/airflow_env/lib/python3.12/site-packages/airflow/utils/operator_helpers.py", line 252, in run
    return self.func(*args, **kwargs)
           ^^^^^^^^^^^^^^^^^^^^^^^^^^
  File "/home/lucas/airflow/dags/DAGInjectPACTRATXAGENDElastic.py", line 148, in inject_data_into_es
    resp = es_client.indices.create(
           ^^^^^^^^^^^^^^^^^^^^^^^^^
  File "/home/lucas/airflow_env/lib/python3.12/site-packages/elasticsearch/_sync/client/utils.py", line 455, in wrapped
    return api(*args, **kwargs)
           ^^^^^^^^^^^^^^^^^^^^
  File "/home/lucas/airflow_env/lib/python3.12/site-packages/elasticsearch/_sync/client/indices.py", line 633, in create
    return self.perform_request(  # type: ignore[return-value]
           ^^^^^^^^^^^^^^^^^^^^^^^^^^^^^^^^^^^^^^^^^^^^^^^^^^^
  File "/home/lucas/airflow_env/lib/python3.12/site-packages/elasticsearch/_sync/client/_base.py", line 423, in perform_request
    return self._client.perform_request(
           ^^^^^^^^^^^^^^^^^^^^^^^^^^^^^
  File "/home/lucas/airflow_env/lib/python3.12/site-packages/elasticsearch/_sync/client/_base.py", line 271, in perform_request
    response = self._perform_request(
               ^^^^^^^^^^^^^^^^^^^^^^
  File "/home/lucas/airflow_env/lib/python3.12/site-packages/elasticsearch/_sync/client/_base.py", line 316, in _perform_request
    meta, resp_body = self.transport.perform_request(
                      ^^^^^^^^^^^^^^^^^^^^^^^^^^^^^^^
  File "/home/lucas/airflow_env/lib/python3.12/site-packages/elastic_transport/_transport.py", line 342, in perform_request
    resp = node.perform_request(
           ^^^^^^^^^^^^^^^^^^^^^
  File "/home/lucas/airflow_env/lib/python3.12/site-packages/elastic_transport/_node/_http_urllib3.py", line 202, in perform_request
    raise err from e
elastic_transport.ConnectionError: Connection error caused by: ConnectionError(Connection error caused by: NewConnectionError(<urllib3.connection.HTTPConnection object at 0x743fe18e4560>: Failed to establish a new connection: [Errno 111] Connection refused))
[2025-01-27T20:02:13.329-0300] {local_task_job_runner.py:266} INFO - Task exited with return code 1
[2025-01-27T20:02:13.355-0300] {taskinstance.py:3895} INFO - 0 downstream tasks scheduled from follow-on schedule check
[2025-01-27T20:02:13.356-0300] {local_task_job_runner.py:245} INFO - ::endgroup::
