[2025-01-26T22:18:25.994-0300] {local_task_job_runner.py:123} INFO - ::group::Pre task execution logs
[2025-01-26T22:18:25.999-0300] {taskinstance.py:2613} INFO - Dependencies all met for dep_context=non-requeueable deps ti=<TaskInstance: InsertIntoElastic.inject_data_into_es scheduled__2022-09-16T00:00:00+00:00 [queued]>
[2025-01-26T22:18:26.003-0300] {taskinstance.py:2613} INFO - Dependencies all met for dep_context=requeueable deps ti=<TaskInstance: InsertIntoElastic.inject_data_into_es scheduled__2022-09-16T00:00:00+00:00 [queued]>
[2025-01-26T22:18:26.003-0300] {taskinstance.py:2866} INFO - Starting attempt 1 of 2
[2025-01-26T22:18:26.013-0300] {taskinstance.py:2889} INFO - Executing <Task(PythonOperator): inject_data_into_es> on 2022-09-16 00:00:00+00:00
[2025-01-26T22:18:26.016-0300] {standard_task_runner.py:72} INFO - Started process 107667 to run task
[2025-01-26T22:18:26.018-0300] {standard_task_runner.py:104} INFO - Running: ['airflow', 'tasks', 'run', 'InsertIntoElastic', 'inject_data_into_es', 'scheduled__2022-09-16T00:00:00+00:00', '--job-id', '5695', '--raw', '--subdir', 'DAGS_FOLDER/DAGInjectElastic.py', '--cfg-path', '/tmp/tmpapusuaum']
[2025-01-26T22:18:26.020-0300] {standard_task_runner.py:105} INFO - Job 5695: Subtask inject_data_into_es
[2025-01-26T22:18:26.046-0300] {task_command.py:467} INFO - Running <TaskInstance: InsertIntoElastic.inject_data_into_es scheduled__2022-09-16T00:00:00+00:00 [running]> on host lucas-Aspire-A514-54
[2025-01-26T22:18:26.097-0300] {taskinstance.py:3132} INFO - Exporting env vars: AIRFLOW_CTX_DAG_OWNER='lucas' AIRFLOW_CTX_DAG_ID='InsertIntoElastic' AIRFLOW_CTX_TASK_ID='inject_data_into_es' AIRFLOW_CTX_EXECUTION_DATE='2022-09-16T00:00:00+00:00' AIRFLOW_CTX_TRY_NUMBER='1' AIRFLOW_CTX_DAG_RUN_ID='scheduled__2022-09-16T00:00:00+00:00'
[2025-01-26T22:18:26.098-0300] {taskinstance.py:731} INFO - ::endgroup::
[2025-01-26T22:18:36.857-0300] {_transport.py:372} INFO - PUT http://localhost:9200/_bulk [status:N/A duration:5.559s]
[2025-01-26T22:18:36.897-0300] {_node_pool.py:249} WARNING - Node <Urllib3HttpNode(http://localhost:9200)> has failed for 1 times in a row, putting on 1 second timeout
[2025-01-26T22:18:37.004-0300] {job.py:229} INFO - Heartbeat recovered after 11.06 seconds
[2025-01-26T22:18:36.897-0300] {_transport.py:415} WARNING - Retrying request after failure (attempt 0 of 3)
Traceback (most recent call last):
  File "/home/lucas/airflow_env/lib/python3.12/site-packages/urllib3/connectionpool.py", line 787, in urlopen
    response = self._make_request(
               ^^^^^^^^^^^^^^^^^^^
  File "/home/lucas/airflow_env/lib/python3.12/site-packages/urllib3/connectionpool.py", line 534, in _make_request
    response = conn.getresponse()
               ^^^^^^^^^^^^^^^^^^
  File "/home/lucas/airflow_env/lib/python3.12/site-packages/urllib3/connection.py", line 516, in getresponse
    httplib_response = super().getresponse()
                       ^^^^^^^^^^^^^^^^^^^^^
  File "/usr/lib/python3.12/http/client.py", line 1428, in getresponse
    response.begin()
  File "/usr/lib/python3.12/http/client.py", line 331, in begin
    version, status, reason = self._read_status()
                              ^^^^^^^^^^^^^^^^^^^
  File "/usr/lib/python3.12/http/client.py", line 292, in _read_status
    line = str(self.fp.readline(_MAXLINE + 1), "iso-8859-1")
               ^^^^^^^^^^^^^^^^^^^^^^^^^^^^^^
  File "/usr/lib/python3.12/socket.py", line 707, in readinto
    return self._sock.recv_into(b)
           ^^^^^^^^^^^^^^^^^^^^^^^
ConnectionResetError: [Errno 104] Connection reset by peer

During handling of the above exception, another exception occurred:

Traceback (most recent call last):
  File "/home/lucas/airflow_env/lib/python3.12/site-packages/elastic_transport/_node/_http_urllib3.py", line 167, in perform_request
    response = self.pool.urlopen(
               ^^^^^^^^^^^^^^^^^^
  File "/home/lucas/airflow_env/lib/python3.12/site-packages/urllib3/connectionpool.py", line 841, in urlopen
    retries = retries.increment(
              ^^^^^^^^^^^^^^^^^^
  File "/home/lucas/airflow_env/lib/python3.12/site-packages/urllib3/util/retry.py", line 449, in increment
    raise reraise(type(error), error, _stacktrace)
          ^^^^^^^^^^^^^^^^^^^^^^^^^^^^^^^^^^^^^^^^
  File "/home/lucas/airflow_env/lib/python3.12/site-packages/urllib3/util/util.py", line 38, in reraise
    raise value.with_traceback(tb)
  File "/home/lucas/airflow_env/lib/python3.12/site-packages/urllib3/connectionpool.py", line 787, in urlopen
    response = self._make_request(
               ^^^^^^^^^^^^^^^^^^^
  File "/home/lucas/airflow_env/lib/python3.12/site-packages/urllib3/connectionpool.py", line 534, in _make_request
    response = conn.getresponse()
               ^^^^^^^^^^^^^^^^^^
  File "/home/lucas/airflow_env/lib/python3.12/site-packages/urllib3/connection.py", line 516, in getresponse
    httplib_response = super().getresponse()
                       ^^^^^^^^^^^^^^^^^^^^^
  File "/usr/lib/python3.12/http/client.py", line 1428, in getresponse
    response.begin()
  File "/usr/lib/python3.12/http/client.py", line 331, in begin
    version, status, reason = self._read_status()
                              ^^^^^^^^^^^^^^^^^^^
  File "/usr/lib/python3.12/http/client.py", line 292, in _read_status
    line = str(self.fp.readline(_MAXLINE + 1), "iso-8859-1")
               ^^^^^^^^^^^^^^^^^^^^^^^^^^^^^^
  File "/usr/lib/python3.12/socket.py", line 707, in readinto
    return self._sock.recv_into(b)
           ^^^^^^^^^^^^^^^^^^^^^^^
urllib3.exceptions.ProtocolError: ('Connection aborted.', ConnectionResetError(104, 'Connection reset by peer'))

The above exception was the direct cause of the following exception:

Traceback (most recent call last):
  File "/home/lucas/airflow_env/lib/python3.12/site-packages/elastic_transport/_transport.py", line 342, in perform_request
    resp = node.perform_request(
           ^^^^^^^^^^^^^^^^^^^^^
  File "/home/lucas/airflow_env/lib/python3.12/site-packages/elastic_transport/_node/_http_urllib3.py", line 202, in perform_request
    raise err from e
elastic_transport.ConnectionError: Connection error caused by: ProtocolError(('Connection aborted.', ConnectionResetError(104, 'Connection reset by peer')))
[2025-01-26T22:18:47.045-0300] {_transport.py:372} INFO - PUT http://localhost:9200/_bulk [status:N/A duration:10.011s]
[2025-01-26T22:18:47.045-0300] {_node_pool.py:249} WARNING - Node <Urllib3HttpNode(http://localhost:9200)> has failed for 2 times in a row, putting on 2 second timeout
[2025-01-26T22:18:47.046-0300] {taskinstance.py:3311} ERROR - Task failed with exception
Traceback (most recent call last):
  File "/home/lucas/airflow_env/lib/python3.12/site-packages/urllib3/connectionpool.py", line 534, in _make_request
    response = conn.getresponse()
               ^^^^^^^^^^^^^^^^^^
  File "/home/lucas/airflow_env/lib/python3.12/site-packages/urllib3/connection.py", line 516, in getresponse
    httplib_response = super().getresponse()
                       ^^^^^^^^^^^^^^^^^^^^^
  File "/usr/lib/python3.12/http/client.py", line 1428, in getresponse
    response.begin()
  File "/usr/lib/python3.12/http/client.py", line 331, in begin
    version, status, reason = self._read_status()
                              ^^^^^^^^^^^^^^^^^^^
  File "/usr/lib/python3.12/http/client.py", line 292, in _read_status
    line = str(self.fp.readline(_MAXLINE + 1), "iso-8859-1")
               ^^^^^^^^^^^^^^^^^^^^^^^^^^^^^^
  File "/usr/lib/python3.12/socket.py", line 707, in readinto
    return self._sock.recv_into(b)
           ^^^^^^^^^^^^^^^^^^^^^^^
TimeoutError: timed out

The above exception was the direct cause of the following exception:

Traceback (most recent call last):
  File "/home/lucas/airflow_env/lib/python3.12/site-packages/elastic_transport/_node/_http_urllib3.py", line 167, in perform_request
    response = self.pool.urlopen(
               ^^^^^^^^^^^^^^^^^^
  File "/home/lucas/airflow_env/lib/python3.12/site-packages/urllib3/connectionpool.py", line 841, in urlopen
    retries = retries.increment(
              ^^^^^^^^^^^^^^^^^^
  File "/home/lucas/airflow_env/lib/python3.12/site-packages/urllib3/util/retry.py", line 449, in increment
    raise reraise(type(error), error, _stacktrace)
          ^^^^^^^^^^^^^^^^^^^^^^^^^^^^^^^^^^^^^^^^
  File "/home/lucas/airflow_env/lib/python3.12/site-packages/urllib3/util/util.py", line 39, in reraise
    raise value
  File "/home/lucas/airflow_env/lib/python3.12/site-packages/urllib3/connectionpool.py", line 787, in urlopen
    response = self._make_request(
               ^^^^^^^^^^^^^^^^^^^
  File "/home/lucas/airflow_env/lib/python3.12/site-packages/urllib3/connectionpool.py", line 536, in _make_request
    self._raise_timeout(err=e, url=url, timeout_value=read_timeout)
  File "/home/lucas/airflow_env/lib/python3.12/site-packages/urllib3/connectionpool.py", line 367, in _raise_timeout
    raise ReadTimeoutError(
urllib3.exceptions.ReadTimeoutError: HTTPConnectionPool(host='localhost', port=9200): Read timed out. (read timeout=9.993421279999893)

The above exception was the direct cause of the following exception:

Traceback (most recent call last):
  File "/home/lucas/airflow_env/lib/python3.12/site-packages/airflow/models/taskinstance.py", line 767, in _execute_task
    result = _execute_callable(context=context, **execute_callable_kwargs)
             ^^^^^^^^^^^^^^^^^^^^^^^^^^^^^^^^^^^^^^^^^^^^^^^^^^^^^^^^^^^^^
  File "/home/lucas/airflow_env/lib/python3.12/site-packages/airflow/models/taskinstance.py", line 733, in _execute_callable
    return ExecutionCallableRunner(
           ^^^^^^^^^^^^^^^^^^^^^^^^
  File "/home/lucas/airflow_env/lib/python3.12/site-packages/airflow/utils/operator_helpers.py", line 252, in run
    return self.func(*args, **kwargs)
           ^^^^^^^^^^^^^^^^^^^^^^^^^^
  File "/home/lucas/airflow_env/lib/python3.12/site-packages/airflow/models/baseoperator.py", line 422, in wrapper
    return func(self, *args, **kwargs)
           ^^^^^^^^^^^^^^^^^^^^^^^^^^^
  File "/home/lucas/airflow_env/lib/python3.12/site-packages/airflow/operators/python.py", line 238, in execute
    return_value = self.execute_callable()
                   ^^^^^^^^^^^^^^^^^^^^^^^
  File "/home/lucas/airflow_env/lib/python3.12/site-packages/airflow/operators/python.py", line 256, in execute_callable
    return runner.run(*self.op_args, **self.op_kwargs)
           ^^^^^^^^^^^^^^^^^^^^^^^^^^^^^^^^^^^^^^^^^^^
  File "/home/lucas/airflow_env/lib/python3.12/site-packages/airflow/utils/operator_helpers.py", line 252, in run
    return self.func(*args, **kwargs)
           ^^^^^^^^^^^^^^^^^^^^^^^^^^
  File "/home/lucas/airflow/dags/DAGInjectElastic.py", line 143, in inject_data_into_es
    result = helpers.bulk(es_client, action)
             ^^^^^^^^^^^^^^^^^^^^^^^^^^^^^^^
  File "/home/lucas/airflow_env/lib/python3.12/site-packages/elasticsearch/helpers/actions.py", line 540, in bulk
    for ok, item in streaming_bulk(
  File "/home/lucas/airflow_env/lib/python3.12/site-packages/elasticsearch/helpers/actions.py", line 453, in streaming_bulk
    for data, (ok, info) in zip(
  File "/home/lucas/airflow_env/lib/python3.12/site-packages/elasticsearch/helpers/actions.py", line 343, in _process_bulk_chunk
    resp = client.bulk(*args, operations=bulk_actions, **kwargs)  # type: ignore[arg-type]
           ^^^^^^^^^^^^^^^^^^^^^^^^^^^^^^^^^^^^^^^^^^^^^^^^^^^^^
  File "/home/lucas/airflow_env/lib/python3.12/site-packages/elasticsearch/_sync/client/utils.py", line 455, in wrapped
    return api(*args, **kwargs)
           ^^^^^^^^^^^^^^^^^^^^
  File "/home/lucas/airflow_env/lib/python3.12/site-packages/elasticsearch/_sync/client/__init__.py", line 816, in bulk
    return self.perform_request(  # type: ignore[return-value]
           ^^^^^^^^^^^^^^^^^^^^^^^^^^^^^^^^^^^^^^^^^^^^^^^^^^^
  File "/home/lucas/airflow_env/lib/python3.12/site-packages/elasticsearch/_sync/client/_base.py", line 271, in perform_request
    response = self._perform_request(
               ^^^^^^^^^^^^^^^^^^^^^^
  File "/home/lucas/airflow_env/lib/python3.12/site-packages/elasticsearch/_sync/client/_base.py", line 316, in _perform_request
    meta, resp_body = self.transport.perform_request(
                      ^^^^^^^^^^^^^^^^^^^^^^^^^^^^^^^
  File "/home/lucas/airflow_env/lib/python3.12/site-packages/elastic_transport/_transport.py", line 342, in perform_request
    resp = node.perform_request(
           ^^^^^^^^^^^^^^^^^^^^^
  File "/home/lucas/airflow_env/lib/python3.12/site-packages/elastic_transport/_node/_http_urllib3.py", line 202, in perform_request
    raise err from e
elastic_transport.ConnectionTimeout: Connection timeout caused by: ConnectionError(Connection error caused by: ProtocolError(('Connection aborted.', ConnectionResetError(104, 'Connection reset by peer'))))
[2025-01-26T22:18:47.074-0300] {taskinstance.py:1225} INFO - Marking task as UP_FOR_RETRY. dag_id=InsertIntoElastic, task_id=inject_data_into_es, run_id=scheduled__2022-09-16T00:00:00+00:00, execution_date=20220916T000000, start_date=20250127T011826, end_date=20250127T011847
[2025-01-26T22:18:47.091-0300] {taskinstance.py:340} INFO - ::group::Post task execution logs
[2025-01-26T22:18:47.091-0300] {standard_task_runner.py:124} ERROR - Failed to execute job 5695 for task inject_data_into_es (Connection timeout caused by: ConnectionError(Connection error caused by: ProtocolError(('Connection aborted.', ConnectionResetError(104, 'Connection reset by peer')))); 107667)
Traceback (most recent call last):
  File "/home/lucas/airflow_env/lib/python3.12/site-packages/urllib3/connectionpool.py", line 534, in _make_request
    response = conn.getresponse()
               ^^^^^^^^^^^^^^^^^^
  File "/home/lucas/airflow_env/lib/python3.12/site-packages/urllib3/connection.py", line 516, in getresponse
    httplib_response = super().getresponse()
                       ^^^^^^^^^^^^^^^^^^^^^
  File "/usr/lib/python3.12/http/client.py", line 1428, in getresponse
    response.begin()
  File "/usr/lib/python3.12/http/client.py", line 331, in begin
    version, status, reason = self._read_status()
                              ^^^^^^^^^^^^^^^^^^^
  File "/usr/lib/python3.12/http/client.py", line 292, in _read_status
    line = str(self.fp.readline(_MAXLINE + 1), "iso-8859-1")
               ^^^^^^^^^^^^^^^^^^^^^^^^^^^^^^
  File "/usr/lib/python3.12/socket.py", line 707, in readinto
    return self._sock.recv_into(b)
           ^^^^^^^^^^^^^^^^^^^^^^^
TimeoutError: timed out

The above exception was the direct cause of the following exception:

Traceback (most recent call last):
  File "/home/lucas/airflow_env/lib/python3.12/site-packages/elastic_transport/_node/_http_urllib3.py", line 167, in perform_request
    response = self.pool.urlopen(
               ^^^^^^^^^^^^^^^^^^
  File "/home/lucas/airflow_env/lib/python3.12/site-packages/urllib3/connectionpool.py", line 841, in urlopen
    retries = retries.increment(
              ^^^^^^^^^^^^^^^^^^
  File "/home/lucas/airflow_env/lib/python3.12/site-packages/urllib3/util/retry.py", line 449, in increment
    raise reraise(type(error), error, _stacktrace)
          ^^^^^^^^^^^^^^^^^^^^^^^^^^^^^^^^^^^^^^^^
  File "/home/lucas/airflow_env/lib/python3.12/site-packages/urllib3/util/util.py", line 39, in reraise
    raise value
  File "/home/lucas/airflow_env/lib/python3.12/site-packages/urllib3/connectionpool.py", line 787, in urlopen
    response = self._make_request(
               ^^^^^^^^^^^^^^^^^^^
  File "/home/lucas/airflow_env/lib/python3.12/site-packages/urllib3/connectionpool.py", line 536, in _make_request
    self._raise_timeout(err=e, url=url, timeout_value=read_timeout)
  File "/home/lucas/airflow_env/lib/python3.12/site-packages/urllib3/connectionpool.py", line 367, in _raise_timeout
    raise ReadTimeoutError(
urllib3.exceptions.ReadTimeoutError: HTTPConnectionPool(host='localhost', port=9200): Read timed out. (read timeout=9.993421279999893)

The above exception was the direct cause of the following exception:

Traceback (most recent call last):
  File "/home/lucas/airflow_env/lib/python3.12/site-packages/airflow/task/task_runner/standard_task_runner.py", line 117, in _start_by_fork
    ret = args.func(args, dag=self.dag)
          ^^^^^^^^^^^^^^^^^^^^^^^^^^^^^
  File "/home/lucas/airflow_env/lib/python3.12/site-packages/airflow/cli/cli_config.py", line 49, in command
    return func(*args, **kwargs)
           ^^^^^^^^^^^^^^^^^^^^^
  File "/home/lucas/airflow_env/lib/python3.12/site-packages/airflow/utils/cli.py", line 116, in wrapper
    return f(*args, **kwargs)
           ^^^^^^^^^^^^^^^^^^
  File "/home/lucas/airflow_env/lib/python3.12/site-packages/airflow/cli/commands/task_command.py", line 483, in task_run
    task_return_code = _run_task_by_selected_method(args, _dag, ti)
                       ^^^^^^^^^^^^^^^^^^^^^^^^^^^^^^^^^^^^^^^^^^^^
  File "/home/lucas/airflow_env/lib/python3.12/site-packages/airflow/cli/commands/task_command.py", line 256, in _run_task_by_selected_method
    return _run_raw_task(args, ti)
           ^^^^^^^^^^^^^^^^^^^^^^^
  File "/home/lucas/airflow_env/lib/python3.12/site-packages/airflow/cli/commands/task_command.py", line 341, in _run_raw_task
    return ti._run_raw_task(
           ^^^^^^^^^^^^^^^^^
  File "/home/lucas/airflow_env/lib/python3.12/site-packages/airflow/utils/session.py", line 97, in wrapper
    return func(*args, session=session, **kwargs)
           ^^^^^^^^^^^^^^^^^^^^^^^^^^^^^^^^^^^^^^
  File "/home/lucas/airflow_env/lib/python3.12/site-packages/airflow/models/taskinstance.py", line 3005, in _run_raw_task
    return _run_raw_task(
           ^^^^^^^^^^^^^^
  File "/home/lucas/airflow_env/lib/python3.12/site-packages/airflow/models/taskinstance.py", line 273, in _run_raw_task
    TaskInstance._execute_task_with_callbacks(
  File "/home/lucas/airflow_env/lib/python3.12/site-packages/airflow/models/taskinstance.py", line 3159, in _execute_task_with_callbacks
    result = self._execute_task(context, task_orig)
             ^^^^^^^^^^^^^^^^^^^^^^^^^^^^^^^^^^^^^^
  File "/home/lucas/airflow_env/lib/python3.12/site-packages/airflow/models/taskinstance.py", line 3183, in _execute_task
    return _execute_task(self, context, task_orig)
           ^^^^^^^^^^^^^^^^^^^^^^^^^^^^^^^^^^^^^^^
  File "/home/lucas/airflow_env/lib/python3.12/site-packages/airflow/models/taskinstance.py", line 767, in _execute_task
    result = _execute_callable(context=context, **execute_callable_kwargs)
             ^^^^^^^^^^^^^^^^^^^^^^^^^^^^^^^^^^^^^^^^^^^^^^^^^^^^^^^^^^^^^
  File "/home/lucas/airflow_env/lib/python3.12/site-packages/airflow/models/taskinstance.py", line 733, in _execute_callable
    return ExecutionCallableRunner(
           ^^^^^^^^^^^^^^^^^^^^^^^^
  File "/home/lucas/airflow_env/lib/python3.12/site-packages/airflow/utils/operator_helpers.py", line 252, in run
    return self.func(*args, **kwargs)
           ^^^^^^^^^^^^^^^^^^^^^^^^^^
  File "/home/lucas/airflow_env/lib/python3.12/site-packages/airflow/models/baseoperator.py", line 422, in wrapper
    return func(self, *args, **kwargs)
           ^^^^^^^^^^^^^^^^^^^^^^^^^^^
  File "/home/lucas/airflow_env/lib/python3.12/site-packages/airflow/operators/python.py", line 238, in execute
    return_value = self.execute_callable()
                   ^^^^^^^^^^^^^^^^^^^^^^^
  File "/home/lucas/airflow_env/lib/python3.12/site-packages/airflow/operators/python.py", line 256, in execute_callable
    return runner.run(*self.op_args, **self.op_kwargs)
           ^^^^^^^^^^^^^^^^^^^^^^^^^^^^^^^^^^^^^^^^^^^
  File "/home/lucas/airflow_env/lib/python3.12/site-packages/airflow/utils/operator_helpers.py", line 252, in run
    return self.func(*args, **kwargs)
           ^^^^^^^^^^^^^^^^^^^^^^^^^^
  File "/home/lucas/airflow/dags/DAGInjectElastic.py", line 143, in inject_data_into_es
    result = helpers.bulk(es_client, action)
             ^^^^^^^^^^^^^^^^^^^^^^^^^^^^^^^
  File "/home/lucas/airflow_env/lib/python3.12/site-packages/elasticsearch/helpers/actions.py", line 540, in bulk
    for ok, item in streaming_bulk(
  File "/home/lucas/airflow_env/lib/python3.12/site-packages/elasticsearch/helpers/actions.py", line 453, in streaming_bulk
    for data, (ok, info) in zip(
  File "/home/lucas/airflow_env/lib/python3.12/site-packages/elasticsearch/helpers/actions.py", line 343, in _process_bulk_chunk
    resp = client.bulk(*args, operations=bulk_actions, **kwargs)  # type: ignore[arg-type]
           ^^^^^^^^^^^^^^^^^^^^^^^^^^^^^^^^^^^^^^^^^^^^^^^^^^^^^
  File "/home/lucas/airflow_env/lib/python3.12/site-packages/elasticsearch/_sync/client/utils.py", line 455, in wrapped
    return api(*args, **kwargs)
           ^^^^^^^^^^^^^^^^^^^^
  File "/home/lucas/airflow_env/lib/python3.12/site-packages/elasticsearch/_sync/client/__init__.py", line 816, in bulk
    return self.perform_request(  # type: ignore[return-value]
           ^^^^^^^^^^^^^^^^^^^^^^^^^^^^^^^^^^^^^^^^^^^^^^^^^^^
  File "/home/lucas/airflow_env/lib/python3.12/site-packages/elasticsearch/_sync/client/_base.py", line 271, in perform_request
    response = self._perform_request(
               ^^^^^^^^^^^^^^^^^^^^^^
  File "/home/lucas/airflow_env/lib/python3.12/site-packages/elasticsearch/_sync/client/_base.py", line 316, in _perform_request
    meta, resp_body = self.transport.perform_request(
                      ^^^^^^^^^^^^^^^^^^^^^^^^^^^^^^^
  File "/home/lucas/airflow_env/lib/python3.12/site-packages/elastic_transport/_transport.py", line 342, in perform_request
    resp = node.perform_request(
           ^^^^^^^^^^^^^^^^^^^^^
  File "/home/lucas/airflow_env/lib/python3.12/site-packages/elastic_transport/_node/_http_urllib3.py", line 202, in perform_request
    raise err from e
elastic_transport.ConnectionTimeout: Connection timeout caused by: ConnectionError(Connection error caused by: ProtocolError(('Connection aborted.', ConnectionResetError(104, 'Connection reset by peer'))))
[2025-01-26T22:18:47.163-0300] {local_task_job_runner.py:266} INFO - Task exited with return code 1
[2025-01-26T22:18:47.172-0300] {taskinstance.py:3895} INFO - 0 downstream tasks scheduled from follow-on schedule check
[2025-01-26T22:18:47.172-0300] {local_task_job_runner.py:245} INFO - ::endgroup::
