[2025-03-22T21:13:36.680-0300] {local_task_job_runner.py:123} INFO - ::group::Pre task execution logs
[2025-03-22T21:13:36.694-0300] {taskinstance.py:2613} INFO - Dependencies all met for dep_context=non-requeueable deps ti=<TaskInstance: ReadPacTrat.readPacTrat scheduled__2020-03-19T03:40:00+00:00 [queued]>
[2025-03-22T21:13:36.704-0300] {taskinstance.py:2613} INFO - Dependencies all met for dep_context=requeueable deps ti=<TaskInstance: ReadPacTrat.readPacTrat scheduled__2020-03-19T03:40:00+00:00 [queued]>
[2025-03-22T21:13:36.705-0300] {taskinstance.py:2866} INFO - Starting attempt 2 of 2
[2025-03-22T21:13:36.727-0300] {taskinstance.py:2889} INFO - Executing <Task(PythonOperator): readPacTrat> on 2020-03-19 03:40:00+00:00
[2025-03-22T21:13:36.732-0300] {standard_task_runner.py:72} INFO - Started process 38203 to run task
[2025-03-22T21:13:36.735-0300] {standard_task_runner.py:104} INFO - Running: ['airflow', 'tasks', 'run', 'ReadPacTrat', 'readPacTrat', 'scheduled__2020-03-19T03:40:00+00:00', '--job-id', '8579', '--raw', '--subdir', 'DAGS_FOLDER/DAGFiltroPacientesTratamento.py', '--cfg-path', '/tmp/tmpdhj_kmfo']
[2025-03-22T21:13:36.737-0300] {standard_task_runner.py:105} INFO - Job 8579: Subtask readPacTrat
[2025-03-22T21:13:36.785-0300] {task_command.py:467} INFO - Running <TaskInstance: ReadPacTrat.readPacTrat scheduled__2020-03-19T03:40:00+00:00 [running]> on host lucas-Aspire-A514-54
[2025-03-22T21:13:36.855-0300] {taskinstance.py:3132} INFO - Exporting env vars: AIRFLOW_CTX_DAG_OWNER='lucas' AIRFLOW_CTX_DAG_ID='ReadPacTrat' AIRFLOW_CTX_TASK_ID='readPacTrat' AIRFLOW_CTX_EXECUTION_DATE='2020-03-19T03:40:00+00:00' AIRFLOW_CTX_TRY_NUMBER='2' AIRFLOW_CTX_DAG_RUN_ID='scheduled__2020-03-19T03:40:00+00:00'
[2025-03-22T21:13:36.856-0300] {taskinstance.py:731} INFO - ::endgroup::
[2025-03-22T21:13:37.099-0300] {taskinstance.py:3311} ERROR - Task failed with exception
Traceback (most recent call last):
  File "/home/lucas/airflow_env/lib/python3.12/site-packages/pandas/core/indexes/base.py", line 3805, in get_loc
    return self._engine.get_loc(casted_key)
           ^^^^^^^^^^^^^^^^^^^^^^^^^^^^^^^^
  File "index.pyx", line 167, in pandas._libs.index.IndexEngine.get_loc
  File "index.pyx", line 196, in pandas._libs.index.IndexEngine.get_loc
  File "pandas/_libs/hashtable_class_helper.pxi", line 7081, in pandas._libs.hashtable.PyObjectHashTable.get_item
  File "pandas/_libs/hashtable_class_helper.pxi", line 7089, in pandas._libs.hashtable.PyObjectHashTable.get_item
KeyError: 'Cidade/UF'

The above exception was the direct cause of the following exception:

Traceback (most recent call last):
  File "/home/lucas/airflow_env/lib/python3.12/site-packages/airflow/models/taskinstance.py", line 767, in _execute_task
    result = _execute_callable(context=context, **execute_callable_kwargs)
             ^^^^^^^^^^^^^^^^^^^^^^^^^^^^^^^^^^^^^^^^^^^^^^^^^^^^^^^^^^^^^
  File "/home/lucas/airflow_env/lib/python3.12/site-packages/airflow/models/taskinstance.py", line 733, in _execute_callable
    return ExecutionCallableRunner(
           ^^^^^^^^^^^^^^^^^^^^^^^^
  File "/home/lucas/airflow_env/lib/python3.12/site-packages/airflow/utils/operator_helpers.py", line 252, in run
    return self.func(*args, **kwargs)
           ^^^^^^^^^^^^^^^^^^^^^^^^^^
  File "/home/lucas/airflow_env/lib/python3.12/site-packages/airflow/models/baseoperator.py", line 422, in wrapper
    return func(self, *args, **kwargs)
           ^^^^^^^^^^^^^^^^^^^^^^^^^^^
  File "/home/lucas/airflow_env/lib/python3.12/site-packages/airflow/operators/python.py", line 238, in execute
    return_value = self.execute_callable()
                   ^^^^^^^^^^^^^^^^^^^^^^^
  File "/home/lucas/airflow_env/lib/python3.12/site-packages/airflow/operators/python.py", line 256, in execute_callable
    return runner.run(*self.op_args, **self.op_kwargs)
           ^^^^^^^^^^^^^^^^^^^^^^^^^^^^^^^^^^^^^^^^^^^
  File "/home/lucas/airflow_env/lib/python3.12/site-packages/airflow/utils/operator_helpers.py", line 252, in run
    return self.func(*args, **kwargs)
           ^^^^^^^^^^^^^^^^^^^^^^^^^^
  File "/home/lucas/airflow/dags/DAGFiltroPacientesTratamento.py", line 29, in read_filter_PACTRAT
    df['Cidade'] = df['Cidade/UF'].str.split('/').str[0].copy()
                   ~~^^^^^^^^^^^^^
  File "/home/lucas/airflow_env/lib/python3.12/site-packages/pandas/core/frame.py", line 4102, in __getitem__
    indexer = self.columns.get_loc(key)
              ^^^^^^^^^^^^^^^^^^^^^^^^^
  File "/home/lucas/airflow_env/lib/python3.12/site-packages/pandas/core/indexes/base.py", line 3812, in get_loc
    raise KeyError(key) from err
KeyError: 'Cidade/UF'
[2025-03-22T21:13:37.105-0300] {taskinstance.py:1225} INFO - Marking task as FAILED. dag_id=ReadPacTrat, task_id=readPacTrat, run_id=scheduled__2020-03-19T03:40:00+00:00, execution_date=20200319T034000, start_date=20250323T001336, end_date=20250323T001337
[2025-03-22T21:13:37.124-0300] {taskinstance.py:340} INFO - ::group::Post task execution logs
[2025-03-22T21:13:37.124-0300] {standard_task_runner.py:124} ERROR - Failed to execute job 8579 for task readPacTrat ('Cidade/UF'; 38203)
Traceback (most recent call last):
  File "/home/lucas/airflow_env/lib/python3.12/site-packages/pandas/core/indexes/base.py", line 3805, in get_loc
    return self._engine.get_loc(casted_key)
           ^^^^^^^^^^^^^^^^^^^^^^^^^^^^^^^^
  File "index.pyx", line 167, in pandas._libs.index.IndexEngine.get_loc
  File "index.pyx", line 196, in pandas._libs.index.IndexEngine.get_loc
  File "pandas/_libs/hashtable_class_helper.pxi", line 7081, in pandas._libs.hashtable.PyObjectHashTable.get_item
  File "pandas/_libs/hashtable_class_helper.pxi", line 7089, in pandas._libs.hashtable.PyObjectHashTable.get_item
KeyError: 'Cidade/UF'

The above exception was the direct cause of the following exception:

Traceback (most recent call last):
  File "/home/lucas/airflow_env/lib/python3.12/site-packages/airflow/task/task_runner/standard_task_runner.py", line 117, in _start_by_fork
    ret = args.func(args, dag=self.dag)
          ^^^^^^^^^^^^^^^^^^^^^^^^^^^^^
  File "/home/lucas/airflow_env/lib/python3.12/site-packages/airflow/cli/cli_config.py", line 49, in command
    return func(*args, **kwargs)
           ^^^^^^^^^^^^^^^^^^^^^
  File "/home/lucas/airflow_env/lib/python3.12/site-packages/airflow/utils/cli.py", line 116, in wrapper
    return f(*args, **kwargs)
           ^^^^^^^^^^^^^^^^^^
  File "/home/lucas/airflow_env/lib/python3.12/site-packages/airflow/cli/commands/task_command.py", line 483, in task_run
    task_return_code = _run_task_by_selected_method(args, _dag, ti)
                       ^^^^^^^^^^^^^^^^^^^^^^^^^^^^^^^^^^^^^^^^^^^^
  File "/home/lucas/airflow_env/lib/python3.12/site-packages/airflow/cli/commands/task_command.py", line 256, in _run_task_by_selected_method
    return _run_raw_task(args, ti)
           ^^^^^^^^^^^^^^^^^^^^^^^
  File "/home/lucas/airflow_env/lib/python3.12/site-packages/airflow/cli/commands/task_command.py", line 341, in _run_raw_task
    return ti._run_raw_task(
           ^^^^^^^^^^^^^^^^^
  File "/home/lucas/airflow_env/lib/python3.12/site-packages/airflow/utils/session.py", line 97, in wrapper
    return func(*args, session=session, **kwargs)
           ^^^^^^^^^^^^^^^^^^^^^^^^^^^^^^^^^^^^^^
  File "/home/lucas/airflow_env/lib/python3.12/site-packages/airflow/models/taskinstance.py", line 3005, in _run_raw_task
    return _run_raw_task(
           ^^^^^^^^^^^^^^
  File "/home/lucas/airflow_env/lib/python3.12/site-packages/airflow/models/taskinstance.py", line 273, in _run_raw_task
    TaskInstance._execute_task_with_callbacks(
  File "/home/lucas/airflow_env/lib/python3.12/site-packages/airflow/models/taskinstance.py", line 3159, in _execute_task_with_callbacks
    result = self._execute_task(context, task_orig)
             ^^^^^^^^^^^^^^^^^^^^^^^^^^^^^^^^^^^^^^
  File "/home/lucas/airflow_env/lib/python3.12/site-packages/airflow/models/taskinstance.py", line 3183, in _execute_task
    return _execute_task(self, context, task_orig)
           ^^^^^^^^^^^^^^^^^^^^^^^^^^^^^^^^^^^^^^^
  File "/home/lucas/airflow_env/lib/python3.12/site-packages/airflow/models/taskinstance.py", line 767, in _execute_task
    result = _execute_callable(context=context, **execute_callable_kwargs)
             ^^^^^^^^^^^^^^^^^^^^^^^^^^^^^^^^^^^^^^^^^^^^^^^^^^^^^^^^^^^^^
  File "/home/lucas/airflow_env/lib/python3.12/site-packages/airflow/models/taskinstance.py", line 733, in _execute_callable
    return ExecutionCallableRunner(
           ^^^^^^^^^^^^^^^^^^^^^^^^
  File "/home/lucas/airflow_env/lib/python3.12/site-packages/airflow/utils/operator_helpers.py", line 252, in run
    return self.func(*args, **kwargs)
           ^^^^^^^^^^^^^^^^^^^^^^^^^^
  File "/home/lucas/airflow_env/lib/python3.12/site-packages/airflow/models/baseoperator.py", line 422, in wrapper
    return func(self, *args, **kwargs)
           ^^^^^^^^^^^^^^^^^^^^^^^^^^^
  File "/home/lucas/airflow_env/lib/python3.12/site-packages/airflow/operators/python.py", line 238, in execute
    return_value = self.execute_callable()
                   ^^^^^^^^^^^^^^^^^^^^^^^
  File "/home/lucas/airflow_env/lib/python3.12/site-packages/airflow/operators/python.py", line 256, in execute_callable
    return runner.run(*self.op_args, **self.op_kwargs)
           ^^^^^^^^^^^^^^^^^^^^^^^^^^^^^^^^^^^^^^^^^^^
  File "/home/lucas/airflow_env/lib/python3.12/site-packages/airflow/utils/operator_helpers.py", line 252, in run
    return self.func(*args, **kwargs)
           ^^^^^^^^^^^^^^^^^^^^^^^^^^
  File "/home/lucas/airflow/dags/DAGFiltroPacientesTratamento.py", line 29, in read_filter_PACTRAT
    df['Cidade'] = df['Cidade/UF'].str.split('/').str[0].copy()
                   ~~^^^^^^^^^^^^^
  File "/home/lucas/airflow_env/lib/python3.12/site-packages/pandas/core/frame.py", line 4102, in __getitem__
    indexer = self.columns.get_loc(key)
              ^^^^^^^^^^^^^^^^^^^^^^^^^
  File "/home/lucas/airflow_env/lib/python3.12/site-packages/pandas/core/indexes/base.py", line 3812, in get_loc
    raise KeyError(key) from err
KeyError: 'Cidade/UF'
[2025-03-22T21:13:37.148-0300] {local_task_job_runner.py:266} INFO - Task exited with return code 1
[2025-03-22T21:13:37.161-0300] {taskinstance.py:3895} INFO - 0 downstream tasks scheduled from follow-on schedule check
[2025-03-22T21:13:37.162-0300] {local_task_job_runner.py:245} INFO - ::endgroup::
